Workbook
Name データタイプ: '99_マスタ'!#REF!
Name 概念: '99_マスタ'!#REF!
Name 業務カテゴリ: '99_マスタ'!#REF!
Name 指標タイプ: '99_マスタ'!#REF!
Name 定義状態: '99_マスタ'!#REF!
Name 優先度: '99_マスタ'!#REF!

Sheet ★指標_用語辞書
B2: No | C2: 経営ダッシュボード | D2: 確認部門 | E2: 分科① | F2: 分科② | G2: 分科③ | H2: 分科④ | I2: 分科⑤ | J2: 分科⑥ | K2: 指標大分類 | L2: 指標タイプ Lv.1 | M2: 指標タイプ Lv.2 | N2: 指標タイプ Lv.3 | O2: 今後の正式名称 | P2: 現時点の資料での出現用語 | Q2: 略称/同義語 | R2: 定義 | S2: 算出式 / 構造 | T2: 単位 | U2: 使用シーン / 主な帳票 | Z2: 出典 | AH2: 要修正フラグ | AI2: 修正後 | AL2: e
U3: 営業 | V3: マーケ | W3: 生産 | X3: SCM | Y3: 経営戦略 ・収益企画 | Z3: 営業 | AA3: マーケ | AB3: 生産 | AC3: SCM | AD3: 経営戦略 ・収益企画 | AE3: 備考 | AF3: 確認対象部門 | AG3: 収益企画部担当者 | AH3: ドラフトに誤りがある場合1を記載 | AI3: 定義 | AJ3: 算出式 / 構造 | AK3: 単位 | AL3: e
B4: =ROW()-3 -> 1 | C4: ○ | K4: A_指標 | L4: 01_財務指標 | M4: 01_PL | N4: 売上高 | O4: 総売上高 | P4: 総売上高 | Q4: 総売 | R4: 控除を行っていない売上の合計額。ロッテの場合は仕切り価格販売の積み上げ | S4: 販売数量×単価（仕切価格） | T4: 円 | U4: 全国営業会議, 営業政策, 予算表 | V4: — | W4: — | X4: 商品規格適正化検討、ロッテ業績 | Y4: 個別決算 | Z4: 営政, 全営 | AA4: — | AB4: — | AC4: SCM会議、ロッテ業績簡易版 | AD4: 2月個別決算 | AF4: 収益企画 | AH4: 1 | AI4: 控除を行っていない売上の合計額。SAPで計上された売上の合計額。 | AJ4: 販売数量×単価（実際に販売先に販売した単価）の積み上げ | AK4: 円 | AL4: e
B5: =ROW()-3 -> 2 | K5: A_指標 | L5: 01_財務指標 | M5: 01_PL | N5: 売上高 | O5: 総売上高 | P5: 売上（控除前） | Q5: ー | R5: 売上控除項目（年契リベート・販促協賛金等の取引先への割戻し）を差し引く前の売上高。事業損益表において各種比率（特売費率・販売費計率等）の分母として使用される基準売上。控除後の純売上高とは異なり、割戻し前の総額ベースの売上を示す | S5: 純売上高 ＋ 売上控除額 | T5: 円 | U5: 事業損益 | V5: — | W5: — | X5: — | Y5: — | Z5: 全営 | AA5: — | AB5: — | AC5: — | AD5: — | AL5: e
B6: =ROW()-3 -> 3 | C6: ○ | K6: A_指標 | L6: 01_財務指標 | M6: 01_PL | N6: 売上高 | O6: 純売上高 | P6: 純売上高 | Q6: 純売ベース、純売 | R6: 総売上から返品・値引等を控除した売上。営業利益の率計算の分母として使用される。 | S6: 総売上 − 値引・返品・販売費（一部） | T6: 円 | U6: 品目別営業利益（純売ベース）, 営業会議資料 | V6: 新商品マーケット分析 | W6: — | X6: — | Y6: 個別決算 | Z6: 全営 | AA6: アジア恋ナレッジ | AB6: — | AC6: — | AD6: 2月個別決算、本部KPI確認 | AF6: 収益企画 | AH6: 1 | AI6: 総売上高から特売費等の控除対象経費を差し引いた売上。 | AJ6: 総売上高 − 売上控除 | AK6: 円 | AL6: e
B7: =ROW()-3 -> 4 | C7: ○ | K7: A_指標 | L7: 01_財務指標 | M7: 01_PL | N7: 売上高 | O7: 純売上高 | P7: 売上 | Q7: 売上高 | R7: 純売上高を売上高として記載 | T7: 円 | U7: — | V7: — | W7: — | X7: — | Y7: KK定例会長報告 | Z7: — | AA7: — | AB7: — | AC7: — | AD7: KK定例会長報告 | AL7: e
B8: =ROW()-3 -> 5 | K8: A_指標 | L8: 01_財務指標 | M8: 01_PL | N8: 売上高 | O8: 海外事業計（現地会計基準） | P8: 海外事業計（現地会計基準） | Q8: 海外事業計 | R8: ㈱ロッテの資料では、海外現法（アジア計＋ウェデル計）の純売上高・営業利益を現地の会計基準で集計した合計。社内レートで円換算して表示。 | S8: アジア計（タイ・インドネシア・ベトナム・台湾）+ ウェデル計（ウェデル・ウェデルカフェ） | T8: 円 | U8: — | V8: — | W8: — | X8: — | Y8: 個別決算報告（海外現法） | Z8: — | AA8: — | AB8: — | AC8: — | AD8: 2月個別決算 | AL8: e
B9: =ROW()-3 -> 6 | C9: ○ | K9: A_指標 | L9: 01_財務指標 | M9: 01_PL | N9: 売上高 | O9: 連結売上高 | P9: 連結売上高 | Q9: 連結 | R9: ㈱ロッテおよびグループ会社を連結した売上高。経理の連結決算で使用される概念で、単体（個別）売上とは異なる。 | S9: ・単体売上高 + グループ会社売上 − 内部取引消去 ・単体売上高＋グループ会社売上ー連結修正 | T9: 円 | U9: — | V9: — | W9: — | X9: — | Y9: 個別決算報告（参照概念）、KK定例会長報告（連結決算速報：国内計・海外計・WEDEL等） | Z9: — | AA9: — | AB9: — | AC9: — | AD9: KK定例会長報告 | AF9: 収益企画 経理 | AH9: 1 | AI9: ㈱ロッテおよびグループ会社を連結した売上高。経理の連結決算で使用される概念で、単体（個別）売上とは異なる。 | AJ9: 単体売上高＋グループ会社売上ー連結修正ー為替差額 | AK9: 円 | AL9: e
B10: =ROW()-3 -> 7 | K10: A_指標 | L10: 01_財務指標 | M10: 01_PL | N10: 売上控除 | O10: フィ | P10: フィ | Q10: 基本フィ | R10: 卸店の機能に対する割戻金。DBフィ／社会課題取組フィ／パートナーフィの3区分。 | S10: 売上規模ベース＋機能評価による加算 | T10: %, 円 | U10: 卸取引制度, 基本フィ覚書 | V10: — | W10: — | X10: — | Y10: — | Z10: 菓初, 推進M | AA10: — | AB10: — | AC10: — | AD10: — | AL10: e
B11: =ROW()-3 -> 8 | C11: ○ | K11: A_指標 | L11: 01_財務指標 | M11: 01_PL | N11: 売上控除 | O11: 売上控除 | P11: 売上控除 | Q11: 控除 | R11: 総売上高から差し引かれる控除項目の合計。主に特売費（控除対象）が含まれる。純売上高＝総売上高−売上控除。 | S11: 総売上高 − 純売上高 | T11: 円 | U11: — | V11: — | W11: — | X11: — | Y11: 損益計算書（P/L） | Z11: — | AA11: — | AB11: — | AC11: — | AD11: 2月個別決算, 3月販売実績 | AF11: 収益企画 | AH11: 1 | AI11: 総売上高から差し引かれる控除項目の合計。主に特売費（控除対象）が含まれる。純売上高＝総売上高−売上控除。 | AJ11: フィ＋特売費（控除対象）＋拡売費（控除対象）＋販売店手数料（控除対象）＋経費出荷＋売上控除（輸出）＋手数料（直接取引） | AK11: 円 | AL11: e
B12: =ROW()-3 -> 9 | K12: A_指標 | L12: 01_財務指標 | M12: 01_PL | N12: 売上控除 | O12: センターフィ | P12: センターフィ | Q12: ー | R12: 特売費の種類の一つ。XXX（どのような特売費か要確認） | T12: ー | U12: — | V12: — | W12: — | X12: SCM会議（特売費適正化） | Y12: — | Z12: — | AA12: — | AB12: — | AC12: SCM会議 | AD12: — | AL12: e
B13: =ROW()-3 -> 10 | C13: ○ | K13: A_指標 | L13: 01_財務指標 | M13: 01_PL | N13: 売上控除 | O13: 特売費 | P13: 特売費 | Q13: — | R13: 特売実施で発生する経費全般。控除対象/控除対象外で区別。 | S13: 値差補填 + 特売条件 + 特売拡売費 等 | T13: 円 | U13: Biz, 特売費分析 | V13: — | W13: — | X13: SCM会議（特売費コントロール・値差上限導入検討） | Y13: — | Z13: 営政, 全営 | AA13: — | AB13: — | AC13: SCM会議, 第3回SCM議事録, 第2回SCM議事録 | AD13: — | AF13: 収益企画 | AH13: 1 | AI13: 特売実施で発生する経費全般。控除対象/控除対象外で区別。 | AJ13: 特売費（控除対象）＋特売費（対象外） | AK13: 円 | AL13: e
B14: =ROW()-3 -> 11 | C14: ○ | K14: A_指標 | L14: 01_財務指標 | M14: 01_PL | N14: 売上控除 | O14: 特売費率 | P14: 特売費率 | Q14: — | R14: 売上に対する特売費の比率。営業利益管理の主要KPI。 | S14: 特売費 ÷ 総売上 × 100 | T14: % | U14: 営業政策, 全営の特売費分析 | V14: 損益概況 | W14: — | X14: SCM会議 | Y14: 収益企画社長報告（PLツリー：品目別特売費率管理） | Z14: 営政, 全営 | AA14: 損益共有MTG | AB14: — | AC14: 第2回SCM議事録 | AD14: KK定例会長報告 | AF14: 収益企画 | AH14: 1 | AI14: 売上に対する特売費の比率。営業部門における主要KPI。分母が総売上高の場合と純売上高の場合がある。 | AJ14: 特売費 ÷ 総売上高 × 100 または 特売費 ÷ 純売上高 × 100 | AK14: % | AL14: e
B15: =ROW()-3 -> 12 | K15: A_指標 | L15: 01_財務指標 | M15: 01_PL | N15: 売上控除 | O15: 特売経費率 | P15: 特売経費率 | Q15: 特売費率（総売比） | R15: 売上に占める特売費の割合。品目別・統括支店別・ブランド別に管理し、予算比・前年比で分析する。費用の使用効率を示す指標で、売上増加と特売費削減の両立が目標。 | S15: 特売経費率 = 特売費 ÷ 売上（総売） × 100 | T15: % | U15: 特売費分析, 月次全国営業会議, 営業政策 | V15: — | W15: — | X15: — | Y15: — | Z15: 全営, 営政 | AA15: — | AB15: — | AC15: — | AD15: — | AL15: e
B16: =ROW()-3 -> 13 | C16: ○ | K16: A_指標 | L16: 01_財務指標 | M16: 01_PL | N16: 売上原価 | O16: 売上原価 | P16: 売上原価 | R16: PLの売上原価 | S16: ・原価（変動）＋原価（固定） ・原材料費＋包材費＋外注加工費＋直接労務費＋機械費（変動）＋機械費（固定）＋間接費＋廃棄損＋売上原価調整 | AL16: e
B17: =ROW()-3 -> 14 | K17: A_指標 | L17: 01_財務指標 | M17: 01_PL | N17: 売上原価 | O17: 原価（変動） | P17: 原価（変動） | R17: PLの売上原価の構成要素の１つ | S17: 原材料費＋包材費＋外注加工費＋直接労務費＋機械費（変動） | AL17: e
B18: =ROW()-3 -> 15 | K18: A_指標 | L18: 01_財務指標 | M18: 01_PL | N18: 売上原価 | O18: 原価（固定） | P18: 原価（固定） | R18: PLの売上原価の構成要素の１つ | S18: 機械費（固定）＋間接費＋廃棄損＋売上原価調整 | AL18: e
B19: =ROW()-3 -> 16 | C19: ○ | K19: A_指標 | L19: 01_財務指標 | M19: 01_PL | N19: 売上原価 | O19: 原料費 | P19: 原材料費 | R19: PLの売上原価の構成要素の１つ。原価（変動）の要素の１つ | AH19: 1 | AK19: 円 | AL19: e
B20: =ROW()-3 -> 17 | C20: ○ | K20: A_指標 | L20: 01_財務指標 | M20: 01_PL | N20: 売上原価 | O20: 包材費 | P20: 包材費 | R20: PLの売上原価の構成要素の１つ。原価（変動）の要素の１つ | AH20: 1 | AK20: 円 | AL20: e
C21: ○ | K21: A_指標 | L21: 01_財務指標 | M21: 01_PL | N21: 売上原価 | O21: 原材料費 | AH21: 1 | AJ21: 原料費＋包材費 | AK21: 円
B22: =ROW()-3 -> 19 | C22: ○ | K22: A_指標 | L22: 01_財務指標 | M22: 01_PL | N22: 売上原価 | O22: 外注加工費 | P22: 外注加工費 | R22: PLの売上原価の構成要素の１つ。原価（変動）の要素の１つ | AH22: 1 | AK22: 円 | AL22: e
B23: =ROW()-3 -> 20 | C23: ○ | K23: A_指標 | L23: 01_財務指標 | M23: 01_PL | N23: 売上原価 | O23: 直接労務費 | P23: 直接労務費 | R23: PLの売上原価の構成要素の１つ。原価（変動）の要素の１つ | AH23: 1 | AK23: 円 | AL23: e
B24: =ROW()-3 -> 21 | C24: ○ | K24: A_指標 | L24: 01_財務指標 | M24: 01_PL | N24: 売上原価 | O24: 機械費（変動） | P24: 機械費（変動） | R24: PLの売上原価の構成要素の１つ。原価（変動）の要素の１つ | AH24: 1 | AK24: 円 | AL24: e
B25: =ROW()-3 -> 22 | C25: ○ | K25: A_指標 | L25: 01_財務指標 | M25: 01_PL | N25: 売上原価 | O25: 機械費（固定） | P25: 機械費（固定） | R25: PLの売上原価の構成要素の１つ。原価（固定）の要素の１つ | AH25: 1 | AK25: 円 | AL25: e
B26: =ROW()-3 -> 23 | C26: ○ | K26: A_指標 | L26: 01_財務指標 | M26: 01_PL | N26: 売上原価 | O26: 間接費 | P26: 間接費 | R26: PLの売上原価の構成要素の１つ。原価（固定）の要素の１つ | AH26: 1 | AK26: 円 | AL26: e
B27: =ROW()-3 -> 24 | C27: ○ | K27: A_指標 | L27: 01_財務指標 | M27: 01_PL | N27: 売上原価 | O27: 廃棄損 | P27: 廃棄損 | R27: PLの売上原価の構成要素の１つ。原価（固定）の要素の１つ | AH27: 1 | AK27: 円 | AL27: e
B28: =ROW()-3 -> 25 | C28: ○ | K28: A_指標 | L28: 01_財務指標 | M28: 01_PL | N28: 売上原価 | O28: 売上原価調整 | P28: 売上原価調整 | R28: PLの売上原価の構成要素の１つ。原価（固定）の要素の１つ | AH28: 1 | AK28: 円 | AL28: e
B29: =ROW()-3 -> 26 | C29: ○ | K29: A_指標 | L29: 01_財務指標 | M29: 01_PL | N29: 売上原価 | O29: 売上原価率 | P29: 売上原価率 | Q29: 原価率 | R29: 純売上高に対する売上原価の比率。製造コスト効率を示す主要管理指標。 | S29: 売上原価 ÷ 純売上高 × 100 | T29: % | U29: — | V29: — | W29: 生産本部月次管理（原価率実績・予算差管理） | X29: — | Y29: KK定例会長報告 | Z29: — | AA29: — | AB29: 会長報告生産3月 | AC29: — | AD29: KK定例会長報告,2月個別決算 | AE29: ・KK定例会長報告では純売上高に対する売上原価率を算出、個別決算の収益性分析では総売上高に対する売上原価率を算出 | AF29: 収益企画 | AH29: 1 | AI29: 売上に対する売上原価の比率。製造コスト効率を示す主要管理指標。分母が総売上高の場合と純売上高の場合がある。 | AJ29: 売上原価 ÷ 総売上高 × 100 または 売上原価 ÷ 純売上高 × 100 | AK29: % | AL29: e
B30: =ROW()-3 -> 27 | C30: ○ | K30: A_指標 | L30: 01_財務指標 | M30: 01_PL | N30: 売上原価 | O30: 原料費率 | P30: 原料費率 | Q30: — | R30: 売上に対する原料費（原材料費）の比率。カカオ豆等の原料相場の影響を直接受ける主要原価KPI。 | S30: 原料費 ÷ 総売上高（または純売上高）× 100 | T30: % | U30: — | V30: 損益概況 | W30: 生産本部月次管理 | X30: — | Y30: 収益企画社長報告 | Z30: — | AA30: 損益共有MTG | AB30: SCM会議 | AC30: — | AD30: 収益企画社長報告 | AF30: 収益企画 | AH30: 1 | AI30: 売上に対する原料費の比率。分母が総売上高の場合と純売上高の場合がある。 | AJ30: 原料費 ÷ 総売上高 × 100 または 原料費 ÷ 純売上高 × 100 | AK30: ％ | AL30: e
B31: =ROW()-3 -> 28 | C31: ○ | K31: A_指標 | L31: 01_財務指標 | M31: 01_PL | N31: 販管費 | O31: 販管費 | P31: 販管費 | Q31: — | R31: 販売費及び一般管理費の合計。広告宣伝費・運賃・保管料・人件費・一般管理費等を含む。 | S31: 販売費 + 広告宣伝費 + 運賃・保管料 + 人件費 + 一般管理費 | T31: 円 | U31: — | V31: — | W31: — | X31: — | Y31: 損益計算書（P/L） | Z31: — | AA31: — | AB31: — | AC31: — | AD31: 2月個別決算 | AH31: 1 | AI31: 販売費及び一般管理費の合計。広告宣伝費・運賃・保管料・人件費・一般管理費等を含む。 | AJ31: 販売費（控除対象外）+ 広告宣伝費 + 運賃・保管料 + 人件費 + 一般管理費 | AK31: 円 | AL31: e
B32: =ROW()-3 -> 29 | C32: ○ | K32: A_指標 | L32: 01_財務指標 | M32: 01_PL | N32: 販管費 | O32: 販売費 | P32: 販売費 | Q32: ー | R32: 特売費・拡売費等販売に関わる費用 | S32: 注文獲得費（特売費＋拡売費）＋注文獲得促進費控除外（見本費（旧販社分）＋市場対策費＋自動販売機費＋自転車費（販促）＋販売店指導費＋販売店手数料＋その他（販促）） | T32: 円 | U32: — | V32: — | W32: — | X32: — | Y32: 損益計算書（P/L） | Z32: — | AA32: — | AB32: — | AC32: — | AD32: 2月個別決算 | AH32: 1 | AI32: 特売費・拡売費等販売に関わる費用 | AJ32: 注文獲得費（特売費＋拡売費）＋注文獲得促進費控除外（見本費（旧販社分）＋市場対策費＋自動販売機費＋自転車費（販促）＋販売店指導費＋販売店手数料＋その他（販促）） | AK32: 円 | AL32: e
B33: =ROW()-3 -> 30 | C33: ○ | K33: A_指標 | L33: 01_財務指標 | M33: 01_PL | N33: 販管費 | O33: 販売費率（売上控除＋控除対象外） | P33: 販売費率（売上控除＋控除対象外） | Q33: ー | R33: 総売上に対する販売費の比率。 | S33: 販売費 ÷ 総売上高 × 100 | T33: ％ | U33: — | V33: — | W33: — | X33: — | Y33: 収益性分析 | Z33: — | AA33: — | AB33: — | AC33: — | AD33: 2月個別決算 | AF33: 収益企画 | AH33: 1 | AI33: 売上に対する販売費の比率。分母が総売上高の場合と純売上高の場合がある。 | AJ33: 販売費 ÷ 総売上高 × 100 または 販売費 ÷ 純売上高 × 100 | AK33: ％ | AL33: e
B34: =ROW()-3 -> 31 | C34: ○ | K34: A_指標 | L34: 01_財務指標 | M34: 01_PL | N34: 販管費 | O34: 注文獲得費 | P34: 注文獲得費 | R34: PLの販売費の構成要素の１つ | S34: 特売費 （控除対象外）＋拡売費（控除対象外）＋注文獲得費 | T34: 円 | AH34: 1 | AK34: 円 | AL34: e
B35: =ROW()-3 -> 32 | C35: ○ | K35: A_指標 | L35: 01_財務指標 | M35: 01_PL | N35: 販管費 | O35: 拡売費（控除対象外） | P35: 拡売費（控除対象外） | Q35: 注文獲得費 | R35: PLの注文獲得費の構成要素の１つ。ディスプレイ・資材・本部対策など、小売店に支払われないキャンペーン経費。卸店への割戻に充当される本部インセンティブも含む。 | S35: 資材費 + ディスプレイ費 + 本部対策 等 | T35: 円 | U35: 予算編成会議, アクションプラン | V35: — | W35: — | X35: — | Y35: — | Z35: 推進M, 営政 | AA35: — | AB35: — | AC35: — | AD35: — | AH35: 1 | AL35: e
B36: =ROW()-3 -> 33 | C36: ○ | K36: A_指標 | L36: 01_財務指標 | M36: 01_PL | N36: 販管費 | O36: 注文獲得費調整 | P36: 注文獲得費調整 | R36: PLの注文獲得費の構成要素の１つ。 | T36: 円 | AL36: e
B37: =ROW()-3 -> 34 | C37: ○ | K37: A_指標 | L37: 01_財務指標 | M37: 01_PL | N37: 販管費 | O37: 広告宣伝費 | P37: 広告宣伝費 | Q37: — | R37: 広告・宣伝に関する費用 | S37: 宣伝費媒体＋宣伝費その他（ディスプレイ・専門誌・オウンドメディアアド） | T37: 円 | U37: — | V37: — | W37: — | X37: — | Y37: 損益計算書（P/L) | Z37: — | AA37: — | AB37: — | AC37: — | AD37: 2月個別決算 | AH37: 1 | AJ37: 宣伝費媒体＋宣伝費その他 | AK37: 円 | AL37: e
B38: =ROW()-3 -> 35 | C38: ○ | K38: A_指標 | L38: 01_財務指標 | M38: 01_PL | N38: 販管費 | O38: 広告宣伝費率 | P38: 広告宣伝費率 | Q38: — | R38: 総売上高に対する広告宣伝費の割合 | S38: 広告宣伝費計 ÷ 総売上高 | T38: ％ | U38: — | V38: — | W38: — | X38: — | Y38: 収益性分析 | Z38: — | AA38: — | AB38: — | AC38: — | AD38: 2月個別決算 | AE38: ・％と金額どちらが指標になるかは要確認 | AF38: 収益企画 | AH38: 1 | AI38: 売上に対する広告宣伝費の比率。分母が総売上高の場合と純売上高の場合がある。 | AJ38: 広告宣伝費 ÷ 総売上高 × 100 または 広告宣伝費 ÷ 純売上高 × 100 | AK38: ％ | AL38: e
B39: =ROW()-3 -> 36 | C39: ○ | K39: A_指標 | L39: 01_財務指標 | M39: 01_PL | N39: 販管費 | O39: 宣伝費媒体 | P39: 宣伝費媒体 | Q39: ー | R39: テレビ・デジタル・新聞・雑誌等の広告媒体に出稿するための費用。宣伝費全体のうち、制作費（クリエイティブ制作コスト）を除いた媒体掲載・放映に要するコスト。PLツリー上では販売関連費の構成要素として計上される。 | T39: 円 | U39: — | V39: 損益概況 | W39: — | X39: — | Y39: — | Z39: — | AA39: 損益共有MTG | AB39: — | AC39: — | AD39: — | AH39: 1 | AL39: e
B40: =ROW()-3 -> 37 | C40: ○ | K40: A_指標 | L40: 01_財務指標 | M40: 01_PL | N40: 販管費 | O40: 運賃・保管料 | P40: 運賃・保管料 | Q40: SCM費、物流費 | R40: SCMが管轄する一次輸送費、二次配送費、保管・荷役料にその他物流費を加算したKPI | S40: 一次輸送費＋二次配送費＋保管・荷役料＋その他物流費 | T40: 円 | U40: — | V40: — | W40: — | X40: SCM会議（年度KPI） | Y40: — | Z40: — | AA40: — | AB40: — | AC40: SCM会議 | AD40: — | AF40: SCM | AH40: 1 | AI40: ㈱ロッテが管轄する一次輸送費、二次輸送費、保管・荷役料にその他物流費を加算した費用。SCM部門の主要KPI。（SCM本部管轄分のみでも別管理している） | AJ40: 一次輸送費＋二次配送費＋保管・荷役料＋その他物流費 | AK40: 円 | AL40: e
B41: =ROW()-3 -> 38 | C41: ○ | K41: A_指標 | L41: 01_財務指標 | M41: 01_PL | N41: 販管費 | O41: 運賃保管料率 | P41: 運賃保管料率 | Q41: 物流費率 | R41: 売上（総売高）に対する運賃・保管料の比率。物流コスト効率の管理KPI。 | S41: （運賃 + 保管料） ÷ 総売上高 × 100 | T41: % | U41: 全国営業会議（物流費効率化KPI） | V41: — | W41: — | X41: SCM本部会議（物流費率管理） | Y41: 収益性分析、KK定例会長報告、収益企画社長報告 | Z41: 営政, 全営 | AA41: — | AB41: — | AC41: SCM本部会議全体 | AD41: 2月個別決算、KK定例会長報告, 収益企画社長報告 | AF41: SCM | AH41: 1 | AI41: 売上に対する運賃保管料の比率。分母が総売上高の場合と純売上高の場合がある。 | AJ41: 運賃保管料 ÷ 総売上高 × 100 または 運賃保管料 ÷ 純売上高 × 100 | AK41: ％ | AL41: e
...

Sheet マスタ_用語辞書
B2: No | C2: 経営ダッシュボード | D2: 確認部門 | E2: 分科① | F2: 分科② | G2: 分科③ | H2: 分科④ | I2: 分科⑤ | J2: 分科⑥ | K2: 指標大分類 | L2: 指標タイプ Lv.1 | M2: 指標タイプ Lv.2 | N2: 指標タイプ Lv.3 | O2: 今後の正式名称 | P2: 現時点の資料での出現用語 | Q2: 略称/同義語 | R2: 定義 | S2: 算出式 / 構造 | T2: 単位 | U2: 使用シーン / 主な帳票 | Z2: 出典 | AH2: 要修正フラグ | AI2: 修正後 | AL2: e
U3: 営業 | V3: マーケ | W3: 生産 | X3: SCM | Y3: 経営戦略 ・収益企画 | Z3: 営業 | AA3: マーケ | AB3: 生産 | AC3: SCM | AD3: 経営戦略 ・収益企画 | AE3: 備考 | AF3: 確認対象部門 | AG3: 収益企画部担当者 | AH3: ドラフトに誤りがある場合1を記載 | AI3: 定義 | AJ3: 算出式 / 構造 | AK3: 単位 | AL3: e
B4: =ROW()-3 -> 1 | K4: B_マスタ | L4: 01_商品・ブランドマスタ | O4: 21963 2袋トッポ | P4: 21963 2袋トッポ | Q4: ー | R4: トッポブランドの2袋パック品を集計した小計。 | S4: トッポ（各品） | U4: — | V4: — | W4: — | X4: チョコレート生産計画表 | Y4: — | Z4: — | AA4: — | AB4: — | AC4: 月末事前チョコ, 協力チョコ, 滋賀チョコ, KYチョコ | AD4: — | AL4: e
B5: =ROW()-3 -> 2 | K5: B_マスタ | L5: 01_商品・ブランドマスタ | O5: 22351クランキービッツ | P5: 22351クランキービッツ | Q5: ー | R5: クランキービッツブランドの全品目を集計した小計。 | S5: クランキービッツ ＋ クランキービッツ'26 | U5: — | V5: — | W5: — | X5: チョコレート生産計画表 | Y5: — | Z5: — | AA5: — | AB5: — | AC5: 月末事前チョコ, 協力チョコ, 滋賀チョコ, KYチョコ | AD5: — | AL5: e
B6: =ROW()-3 -> 3 | K6: B_マスタ | L6: 01_商品・ブランドマスタ | O6: 35Gガーナミルク | P6: 35Gガーナミルク | Q6: ー | R6: 35g規格のガーナミルクチョコレート品を集計した小計。 | S6: 35Gガーナミルク | U6: — | V6: — | W6: — | X6: チョコレート生産計画表 | Y6: — | Z6: — | AA6: — | AB6: — | AC6: 月末事前チョコ, 協力チョコ, 滋賀チョコ, KYチョコ | AD6: — | AL6: e
B7: =ROW()-3 -> 4 | C7: ○ | K7: B_マスタ | L7: 01_商品・ブランドマスタ | O7: HAPPY HAPPY | P7: HAPPY HAPPY | Q7: ー | R7: HAPPY HAPPYブランドの全品目を集計した小計。 | S7: HAPPY HAPPY SP | U7: — | V7: — | W7: — | X7: チョコレート生産計画表 | Y7: — | Z7: — | AA7: — | AB7: — | AC7: 月末事前チョコ, 協力チョコ, 滋賀チョコ, KYチョコ | AD7: — | AL7: e
B8: =ROW()-3 -> 5 | C8: ○ | K8: B_マスタ | L8: 01_商品・ブランドマスタ | O8: LATTE MILKグループ | P8: LATTE MILK | Q8: ー | R8: LATTE MILKブランドの全品目を集計した小計。 | S8: LATTE MILK ＋ LATTE MILK（ポケモン） ＋ LATTE MILK'26（外装変更） ＋ LATTE MILK'26減量 ＋ LATTE MILK大容量 | U8: — | V8: — | W8: — | X8: チョコレート生産計画表 | Y8: — | Z8: — | AA8: — | AB8: — | AC8: 月末事前チョコ, 協力チョコ, 滋賀チョコ, KYチョコ | AD8: — | AL8: e
B9: =ROW()-3 -> 6 | C9: ○ | K9: B_マスタ | L9: 01_商品・ブランドマスタ | O9: LATTE MILK | P9: LATTE MILK | Q9: ラテミルク | R9: 2026年4月発売のロッテのチョコレート商品。発売初月で1,050百万円の売上貢献。チョコレートカテゴリーの新規ブランドとして年度実績に寄与。 | T9: 円 | U9: チョコ新商品提案, 月次実績振り返り | V9: — | W9: — | X9: — | Y9: — | Z9: 全営 | AA9: — | AB9: — | AC9: — | AD9: — | AL9: e
B10: =ROW()-3 -> 7 | C10: ○ | K10: B_マスタ | L10: 01_商品・ブランドマスタ | O10: アーモンド | P10: アーモンド | Q10: ー | R10: アーモンドチョコレートブランド全品（浦和・九州工場合算）の最上位集計行。 | S10: アーモンド ＋ アーモンド準チョコ化25/9 ＋ アーモンド'26（浦和分＋九州分） | U10: — | V10: — | W10: — | X10: チョコレート生産計画表 | Y10: — | Z10: — | AA10: — | AB10: — | AC10: 月末事前チョコ, 協力チョコ, 滋賀チョコ, KYチョコ | AD10: — | AL10: e
B11: =ROW()-3 -> 8 | C11: ○ | K11: B_マスタ | L11: 01_商品・ブランドマスタ | O11: アーモンドSP | P11: アーモンドSP | Q11: ー | R11: アーモンドチョコレートのSP品を集計した小計。 | S11: アーモンドSP VD ＋ アーモンドSP通常 ＋ アーモンドSP準チョコ化25/9 ＋ アーモンドSP'26 | U11: — | V11: — | W11: — | X11: チョコレート生産計画表 | Y11: — | Z11: — | AA11: — | AB11: — | AC11: 月末事前チョコ, 協力チョコ, 滋賀チョコ, KYチョコ | AD11: — | AL11: e
B12: =ROW()-3 -> 9 | C12: ○ | K12: B_マスタ | L12: 01_商品・ブランドマスタ | O12: アーモンドカリっと香ばしPJ | P12: アーモンドカリっと香ばしPJ | Q12: ー | R12: アーモンドカリっと香ばしシリーズのPJ品を集計した小計。 | S12: カリっとPJ増量 ＋ カリっとPJ通常 ＋ カリっと香ばしアーモンドPJ準チョコ化 ＋ カリっと香ばしアーモンドPJ'26 | U12: — | V12: — | W12: — | X12: チョコレート生産計画表 | Y12: — | Z12: — | AA12: — | AB12: — | AC12: 月末事前チョコ, 協力チョコ, 滋賀チョコ, KYチョコ | AD12: — | AL12: e
B13: =ROW()-3 -> 10 | C13: ○ | K13: B_マスタ | L13: 01_商品・ブランドマスタ | O13: アーモンドクリスプ | P13: アーモンドクリスプ | Q13: ー | R13: アーモンドクリスプブランド全品（浦和・九州工場合算）の最上位集計行。 | S13: アーモンドクリスプ ＋ アーモンドクリスプ準チョコ化25/9 ＋ アーモンドクリスプ'26（浦和分＋九州分） | U13: — | V13: — | W13: — | X13: チョコレート生産計画表 | Y13: — | Z13: — | AA13: — | AB13: — | AC13: 月末事前チョコ, 協力チョコ, 滋賀チョコ, KYチョコ | AD13: — | AL13: e
B14: =ROW()-3 -> 11 | C14: ○ | K14: B_マスタ | L14: 01_商品・ブランドマスタ | O14: アーモンドビターPJ | P14: アーモンドビターPJ | Q14: ー | R14: アーモンドビターシリーズのPJ品を集計した小計。 | S14: とろける旨チョコ仕立て ＋ ザクザクとまらんアーモンドPJ ＋ リッチアーモンドチョコレートポップジョイ9か月 ＋ リッチアーモンドチョコレートポップジョイ'26 ＋ リッチアーモンドチョコレートPJ'26秋 | U14: — | V14: — | W14: — | X14: チョコレート生産計画表 | Y14: — | Z14: — | AA14: — | AB14: — | AC14: 月末事前チョコ, 協力チョコ, 滋賀チョコ, KYチョコ | AD14: — | AL14: e
B15: =ROW()-3 -> 12 | C15: ○ | K15: B_マスタ | L15: 01_商品・ブランドマスタ | O15: アジアに恋して | P15: アジアに恋して | Q15: ー | R15: ロッテのプレミアムアイスブランド。アジアの食文化をテーマにした風味（烏龍ミルクティー・杏仁豆腐・ジャスミンミルクティー等）を展開。若年女性向けのデイリープレミアム訴求ブランド。 | T15: — | U15: プレミアム売場獲得・バンドル提案・アイス重点施策 | V15: プレミアムアイスブランド戦略・TVCM施策 | W15: — | X15: — | Y15: — | Z15: 営政 | AA15: アジア恋ナレッジ | AB15: — | AC15: — | AD15: — | AL15: e
B16: =ROW()-3 -> 13 | K16: B_マスタ | L16: 01_商品・ブランドマスタ | O16: 育成ブランド | P16: 育成ブランド | Q16: ー | R16: ロッテのアイスブランドの内、ガーナ・LBの合計 売上控除前のBO売上を使用 | S16: ガーナ + LB | T16: 円 | U16: — | V16: — | W16: — | X16: — | Y16: 経営報告 | Z16: — | AA16: — | AB16: — | AC16: — | AD16: 3月販売実績 | AL16: e
B17: =ROW()-3 -> 14 | C17: ○ | K17: B_マスタ | L17: 01_商品・ブランドマスタ | O17: いちごつみ | P17: いちごつみ | Q17: ー | R17: いちごつみブランドの全品目を集計した小計。 | S17: いちごつみ | U17: — | V17: — | W17: — | X17: チョコレート生産計画表 | Y17: — | Z17: — | AA17: — | AB17: — | AC17: 月末事前チョコ, 協力チョコ, 滋賀チョコ, KYチョコ | AD17: — | AL17: e
B18: =ROW()-3 -> 15 | K18: B_マスタ | L18: 01_商品・ブランドマスタ | O18: エクセレント(B-5,S-6) | P18: エクセレント(B-5,S-6) | Q18: ー | R18: B-5・S-6ラインで製造するエクセレントシリーズ全品を集計したシート内最上位集計行。 | S18: ガーナミルクEX ＋ ガーナローストミルクEX ＋ ガーナブラックEX ＋ クランキーEX | U18: — | V18: — | W18: — | X18: チョコレート生産計画表 | Y18: — | Z18: — | AA18: — | AB18: — | AC18: 月末事前チョコ, 協力チョコ, 滋賀チョコ, KYチョコ | AD18: — | AL18: e
B19: =ROW()-3 -> 16 | C19: ○ | K19: B_マスタ | L19: 01_商品・ブランドマスタ | O19: オオツブガーナ | P19: オオツブガーナ | Q19: ー | R19: オオツブガーナブランドの全品目を集計した小計。 | S19: 大粒ガーナ'25 ＋ 大粒ガーナ'26外品変更 ＋ 大粒ガーナ'26配合変更 | T19: 円 | U19: — | V19: — | W19: — | X19: チョコレート生産計画表 | Y19: — | Z19: — | AA19: — | AB19: — | AC19: 月末事前チョコ, 協力チョコ, 滋賀チョコ, KYチョコ | AD19: — | AL19: e
B20: =ROW()-3 -> 17 | C20: ○ | K20: B_マスタ | L20: 01_商品・ブランドマスタ | O20: ガーナPJ | P20: ガーナPJ | Q20: ー | R20: ガーナブランドのPJ品を集計した小計。 | S20: ガーナPJ周年 ＋ ガーナPJ ＋ ガーナPJ'26 | T20: 円 | U20: — | V20: — | W20: — | X20: チョコレート生産計画表 | Y20: — | Z20: — | AA20: — | AB20: — | AC20: 月末事前チョコ, 協力チョコ, 滋賀チョコ, KYチョコ | AD20: — | AL20: e
B21: =ROW()-3 -> 18 | C21: ○ | K21: B_マスタ | L21: 01_商品・ブランドマスタ | O21: ガーナザクほろPJ | P21: ガーナザクほろPJ | Q21: ー | R21: ガーナザクほろシリーズのPJ品を集計した小計。 | S21: ガーナザクほろココアシュー＆クッキーポップジョイ ＋ ガーナザクほろシュー＆クッキー＜塩ミルク＞ポップジョイ ＋ ガーナザクほろ発酵バターシューPJ | T21: 円 | U21: — | V21: — | W21: — | X21: チョコレート生産計画表 | Y21: — | Z21: — | AA21: — | AB21: — | AC21: 月末事前チョコ, 協力チョコ, 滋賀チョコ, KYチョコ | AD21: — | AL21: e
B22: =ROW()-3 -> 19 | C22: ○ | K22: B_マスタ | L22: 01_商品・ブランドマスタ | O22: ガーナスリムパック | P22: ガーナスリムパック | Q22: ー | R22: ガーナブランドのスリムパック品を集計した小計。 | S22: ガーナスリムパック'25 | T22: 円 | U22: — | V22: — | W22: — | X22: チョコレート生産計画表 | Y22: — | Z22: — | AA22: — | AB22: — | AC22: 月末事前チョコ, 協力チョコ, 滋賀チョコ, KYチョコ | AD22: — | AL22: e
B23: =ROW()-3 -> 20 | C23: ○ | K23: B_マスタ | L23: 01_商品・ブランドマスタ | O23: ガーナピンク | P23: ガーナピンク | Q23: ー | R23: ガーナピンクブランドの全品目を集計した小計。 | S23: ガーナピンク（各品） | T23: 円 | U23: — | V23: — | W23: — | X23: チョコレート生産計画表 | Y23: — | Z23: — | AA23: — | AB23: — | AC23: 月末事前チョコ, 協力チョコ, 滋賀チョコ, KYチョコ | AD23: — | AL23: e
B24: =ROW()-3 -> 21 | C24: ○ | K24: B_マスタ | L24: 01_商品・ブランドマスタ | O24: ガーナブラック | P24: ガーナブラック | Q24: ー | R24: ガーナブラックチョコレートブランドの全品目を集計した小計。 | S24: ガーナブラック母の日 ＋ ガーナブラック'25 ＋ ガーナブラック'26母の日 ＋ ガーナブラック'26賞味 | T24: 円 | U24: — | V24: — | W24: — | X24: チョコレート生産計画表 | Y24: — | Z24: — | AA24: — | AB24: — | AC24: 月末事前チョコ, 協力チョコ, 滋賀チョコ, KYチョコ | AD24: — | AL24: e
B25: =ROW()-3 -> 22 | C25: ○ | K25: B_マスタ | L25: 01_商品・ブランドマスタ | O25: ガーナブラックEX | P25: ガーナブラックEX | Q25: ー | R25: ガーナブラックのエクセレント品を集計した小計。 | S25: ガーナブラックEX'25 ＋ ガーナブラックEX'26 | T25: 円 | U25: — | V25: — | W25: — | X25: チョコレート生産計画表 | Y25: — | Z25: — | AA25: — | AB25: — | AC25: 月末事前チョコ, 協力チョコ, 滋賀チョコ, KYチョコ | AD25: — | AL25: e
B26: =ROW()-3 -> 23 | C26: ○ | K26: B_マスタ | L26: 01_商品・ブランドマスタ | O26: ガーナホワイト | P26: ガーナホワイト | Q26: ー | R26: ガーナホワイトチョコレートブランドの全品目を集計した小計。 | S26: ガーナホワイト母の日 ＋ ガーナホワイト'25 ＋ ガーナホワイト'26母の日 ＋ ガーナホワイト'26賞味 | T26: 円 | U26: — | V26: — | W26: — | X26: チョコレート生産計画表 | Y26: — | Z26: — | AA26: — | AB26: — | AC26: 月末事前チョコ, 協力チョコ, 滋賀チョコ, KYチョコ | AD26: — | AL26: e
B27: =ROW()-3 -> 24 | C27: ○ | K27: B_マスタ | L27: 01_商品・ブランドマスタ | O27: ガーナミルク | P27: ガーナミルク | Q27: ー | R27: ガーナミルクチョコレートブランドの全品目を集計した小計。 | S27: ガーナミルク母の日 ＋ ガーナミルク'25 ＋ ガーナミルク'26母の日 ＋ ガーナミルク'26賞味 ＋ ガーナミルク10箱入 | T27: 円 | U27: — | V27: — | W27: — | X27: チョコレート生産計画表 | Y27: — | Z27: — | AA27: — | AB27: — | AC27: 月末事前チョコ, 協力チョコ, 滋賀チョコ, KYチョコ | AD27: — | AL27: e
B28: =ROW()-3 -> 25 | C28: ○ | K28: B_マスタ | L28: 01_商品・ブランドマスタ | O28: ガーナミルクEX | P28: ガーナミルクEX | Q28: ー | R28: ガーナミルクのエクセレント品を集計した小計。 | S28: ガーナミルクEX'25 | T28: 円 | U28: — | V28: — | W28: — | X28: チョコレート生産計画表 | Y28: — | Z28: — | AA28: — | AB28: — | AC28: 月末事前チョコ, 協力チョコ, 滋賀チョコ, KYチョコ | AD28: — | AL28: e
B29: =ROW()-3 -> 26 | C29: ○ | K29: B_マスタ | L29: 01_商品・ブランドマスタ | O29: ガーナミルクトットプチ | P29: ガーナミルクトットプチ | Q29: ー | R29: ガーナミルクのトットプチ品を集計した小計。 | S29: ガーナミルクトットプチ ＋ ガーナミルクトットプチ'26 | T29: 円 | U29: — | V29: — | W29: — | X29: チョコレート生産計画表 | Y29: — | Z29: — | AA29: — | AB29: — | AC29: 月末事前チョコ, 協力チョコ, 滋賀チョコ, KYチョコ | AD29: — | AL29: e
B30: =ROW()-3 -> 27 | C30: ○ | K30: B_マスタ | L30: 01_商品・ブランドマスタ | O30: ガーナミルクボトル | P30: ガーナミルクボトル | Q30: ー | R30: ガーナミルクのボトル容器品を集計した小計。 | S30: ガーナミルクボトル | T30: 円 | U30: — | V30: — | W30: — | X30: チョコレート生産計画表 | Y30: — | Z30: — | AA30: — | AB30: — | AC30: 月末事前チョコ, 協力チョコ, 滋賀チョコ, KYチョコ | AD30: — | AL30: e
... B36: =ROW()-3 -> 33 | C36: ○ | K36: B_マスタ | L36: 01_商品・ブランドマスタ | O36: ガーナ抹茶 | P36: ガーナ抹茶 | Q36: ー | R36: ガーナ抹茶ブランドの全品目を集計した小計。 | S36: ガーナ抹茶（下期定番化） ＋ ガーナ抹茶'26母の日 ＋ ガーナ抹茶'26秋 | T36: 円 | U36: — | V36: — | W36: — | X36: チョコレート生産計画表 | Y36: — | Z36: — | AA36: — | AB36: — | AC36: 月末事前チョコ, 協力チョコ, 滋賀チョコ, KYチョコ | AD36: — | AL36: e
B37: =ROW()-3 -> 34 | C37: ○ | K37: B_マスタ | L37: 01_商品・ブランドマスタ | O37: カカオの恵み×ゼロ袋 | P37: カカオの恵み×ゼロ袋 | Q37: ー | R37: カカオの恵みとゼロのコラボ袋タイプ品を集計した小計。 | S37: カカオの恵み＜糖類ゼロ＞袋 | U37: — | V37: — | W37: — | X37: チョコレート生産計画表 | Y37: — | Z37: — | AA37: — | AB37: — | AC37: 月末事前チョコ, 協力チョコ, 滋賀チョコ, KYチョコ | AD37: — | AL37: e
B38: =ROW()-3 -> 35 | C38: ○ | K38: B_マスタ | L38: 01_商品・ブランドマスタ | O38: カカオの恵み×ゼロ大容量 | P38: カカオの恵み×ゼロ大容量 | Q38: ー | R38: カカオの恵みとゼロのコラボ大容量品を集計した小計。 | S38: カカオの恵み＜糖類ゼロ＞大容量 | U38: — | V38: — | W38: — | X38: チョコレート生産計画表 | Y38: — | Z38: — | AA38: — | AB38: — | AC38: 月末事前チョコ, 協力チョコ, 滋賀チョコ, KYチョコ | AD38: — | AL38: e
B39: =ROW()-3 -> 36 | C39: ○ | K39: B_マスタ | L39: 01_商品・ブランドマスタ | O39: カカオの恵みSP | P39: カカオの恵みSP | Q39: ー | R39: カカオの恵みブランドのSP品を集計した小計。 | S39: カカオの恵みSP値上げ減量 ＋ カカオの恵みSP品質変更（カカオ産地） ＋ カカオの恵みSP'26JAN変 | U39: — | V39: — | W39: — | X39: チョコレート生産計画表 | Y39: — | Z39: — | AA39: — | AB39: — | AC39: 月末事前チョコ, 協力チョコ, 滋賀チョコ, KYチョコ | AD39: — | AL39: e
B40: =ROW()-3 -> 37 | C40: ○ | K40: B_マスタ | L40: 01_商品・ブランドマスタ | O40: カカオの恵み箱 | P40: カカオの恵み箱 | Q40: ー | R40: カカオの恵みブランドの箱タイプ品を集計した小計。 | S40: カカオの恵み72%箱'26 | U40: — | V40: — | W40: — | X40: チョコレート生産計画表 | Y40: — | Z40: — | AA40: — | AB40: — | AC40: 月末事前チョコ, 協力チョコ, 滋賀チョコ, KYチョコ | AD40: — | AL40: e
B41: =ROW()-3 -> 38 | C41: ○ | K41: B_マスタ | L41: 01_商品・ブランドマスタ | O41: カジッテ | P41: カジッテ | Q41: KAZITTE | R41: ロッテのハードグミブランド。「カジる、果実感。」をコンセプトに、ハード食感でありながら果実感が存分に楽しめる「果実感引き立て製法」（香り・食感・原料のこだわり）を特徴とする。2025年発売。 | T41: — | U41: 新商品提案・定番採用交渉・施策提案 | V41: — | W41: — | X41: — | Y41: — | Z41: 営政 | AA41: — | AB41: — | AC41: — | AD41: — | AL41: e
B42: =ROW()-3 -> 39 | C42: ○ | K42: B_マスタ | L42: 01_商品・ブランドマスタ | O42: ガナクラSP | P42: ガナクラSP | Q42: ー | R42: ガーナ・クランキーブランドのSP品を集計した小計。 | S42: ガナクラSP ＋ ガナクラSP減量JAN変 ＋ ガナクラSP'26 | U42: — | V42: — | W42: — | X42: チョコレート生産計画表 | Y42: — | Z42: — | AA42: — | AB42: — | AC42: 月末事前チョコ, 協力チョコ, 滋賀チョコ, KYチョコ | AD42: — | AL42: e
B43: =ROW()-3 -> 40 | C43: ○ | K43: B_マスタ | L43: 01_商品・ブランドマスタ | O43: カプッチョ | P43: カプッチョ | Q43: ー | R43: カプッチョブランドの全品目を集計した小計。 | S43: カプッチョ ＋ カプッチョ'26 | U43: — | V43: — | W43: — | X43: チョコレート生産計画表 | Y43: — | Z43: — | AA43: — | AB43: — | AC43: 月末事前チョコ, 協力チョコ, 滋賀チョコ, KYチョコ | AD43: — | AL43: e
B44: =ROW()-3 -> 41 | C44: ○ | K44: B_マスタ | L44: 01_商品・ブランドマスタ | O44: キシリトールガム エンジョイシリーズ | P44: キシリトールガム エンジョイシリーズ | Q44: エンジョイシリーズ | R44: キシリトールブランドの若年層向けフレーバーラインナップ。炭酸飲料フレーバー（コーラ等）やフルーツ・飲料フレーバーを展開し、ガム離反ユーザー・フルーツ系錠菓ユーザー・グミユーザーの取り込みを目的とする。 | T44: — | U44: キシリトール定番獲得・ノンユーザー新規獲得提案 | V44: — | W44: — | X44: — | Y44: — | Z44: 営政 | AA44: — | AB44: — | AC44: — | AD44: — | AL44: e
B45: =ROW()-3 -> 42 | C45: ○ | K45: B_マスタ | L45: 01_商品・ブランドマスタ | O45: キャラメルミルク | P45: キャラメルミルク | Q45: ー | R45: ガーナキャラメルミルクブランドの全品目を集計した小計。 | S45: ガーナキャラメルミルク ＋ ガーナキャラメルミルク'26塩+母の日 | U45: — | V45: — | W45: — | X45: チョコレート生産計画表 | Y45: — | Z45: — | AA45: — | AB45: — | AC45: 月末事前チョコ, 協力チョコ, 滋賀チョコ, KYチョコ | AD45: — | AL45: e
B46: =ROW()-3 -> 43 | C46: ○ | K46: B_マスタ | L46: 01_商品・ブランドマスタ | O46: クラガナSP | P46: クラガナSP | Q46: ー | R46: クランキー・ガーナ合同スペシャルパック品を集計した小計。 | S46: クラガナSP各品 | U46: — | V46: — | W46: — | X46: チョコレート生産計画表 | Y46: — | Z46: — | AA46: — | AB46: — | AC46: 月末事前チョコ, 協力チョコ, 滋賀チョコ, KYチョコ | AD46: — | AL46: e
...

Sheet PL構成項目のマスタ
A1: ※BOのくくり | G1: ※PLのくくり
B2: 大分類 | C2: 中分類 | D2: 小分類 | H2: 大分類 | I2: 中分類 | J2: 小分類
B3: 総売上高 | H3: 総売上高
B4: 売上控除 | C4: フィ | H4: 売上控除 | I4: フィ
C5: 特売費(控除対象) | I5: 特売費（控除対象）
C6: 拡売費(控除対象) | I6: 拡売費（控除対象）
C7: 販売店手数料(控除対象) | I7: 注文獲得促進費（控除対象）
C8: 経費出荷 | I8: 運賃（直取引）
C9: 売上控除(輸出) | I9: 売上割引
C10: 手数料(直接取引) | I10: 手数料（直接取引）
B11: 純売上高 | H11: 純売上高
B12: 売上原価 | C12: 原料費 | H12: 売上原価 | I12: 原料費
C13: 包材費 | I13: 包材費
C14: 外注加工費 | D14: 外注原料費 | I14: 外注加工費
D15: 外注包材費 | I15: 直接労務費
D16: 外注成型費 | I16: 機械変動費
D17: 外注 | I17: 減価償却費
C18: 直接労務費 | I18: その他機械費
C19: 機械変動費 | I19: 間接費
C20: 機械固定費 | D20: 減価償却費 | I20: 評価・廃棄損
D21: その他機械費 | I21: 売上原価調整
C22: 間接費 | H22: 売上総利益
C23: 廃棄損 | H23: 販売費 | I23: 注文獲得費 | J23: フィ（控除対象外）
C24: 売上原価調整 | J24: 特売費（控除対象外）
B25: 売上総利益 | J25: 拡売費（控除対象外）
B26: 販売費 | C26: 注文獲得費 | D26: 特売費（控除対象外） | I26: 注文獲得促進費 | J26: 見本費（旧KK分）
D27: 拡売費（控除対象外） | J27: 見本費
D28: 注文獲得費調整 | J28: 市場対策費
C29: 注文獲得促進費 | D29: 販売店手数料（控除対象外） | J29: 自動販売機費
D30: 自動販売機費 | J30: フィールド関連費
D31: 注文獲得促進費（その他） | J31: 自動車費
D32: 注文獲得促進費（輸出） | J32: 販売店指導費
B33: 広告宣伝費 | C33: 媒体 | J33: 販売店手数料
C34: 広告宣伝費（その他） | J34: その他
C35: 広告宣伝費（輸出） | H35: 一般管理費 | I35: 運賃保管料 | J35: 運賃 | K35: 運賃(一次輸送費)
B36: 運賃保管料 | C36: 運賃 | K36: 運賃(二次輸送費)
C37: 保管料 | K37: 運賃(直取引)
C38: 運賃保管料（その他） | K38: 運賃(資材ｾﾝﾀｰ)
C39: 運賃保管料（輸出） | K39: 運賃(その他)
B40: 人件費 | J40: 保管料 | K40: 保管料(一次輸送費)
...

Sheet ★ロッテ用語_用語辞書
B2: No | C2: 経営ダッシュボード | D2: 確認部門 | E2: 分科① | F2: 分科② | G2: 分科③ | H2: 分科④ | I2: 分科⑤ | J2: 分科⑥ | K2: 指標大分類 | L2: 指標タイプ Lv.1 | M2: 指標タイプ Lv.2 | N2: 指標タイプ Lv.3 | O2: 今後の正式名称 | P2: 現時点の資料での出現用語 | Q2: 略称/同義語 | R2: 定義 | S2: 算出式 / 構造 | T2: 単位 | U2: 使用シーン / 主な帳票 | Z2: 出典 | AH2: 要修正フラグ | AI2: 修正後 | AL2: e
U3: 営業 | V3: マーケ | W3: 生産 | X3: SCM | Y3: 経営戦略 ・収益企画 | Z3: 営業 | AA3: マーケ | AB3: 生産 | AC3: SCM | AD3: 経営戦略 ・収益企画 | AE3: 備考 | AF3: 確認対象部門 | AG3: 収益企画部担当者 | AH3: ドラフトに誤りがある場合1を記載 | AI3: 定義 | AJ3: 算出式 / 構造 | AK3: 単位 | AL3: e
B4: =ROW()-3 -> 1 | K4: C_ロッテ用語 | L4: 01_全社 | O4: 5品目 | P4: 5品目 | Q4: 5品目 | R4: ロッテの主要菓子5カテゴリー（ガム・チョコレート・キャンディ・ビスケット・その他?）の合計。全国営業会議・販売実績の集計単位。 | S4: ガム ＋ チョコレート ＋ キャンディ ＋ ビスケット（＋その他？） | T4: 円 | U4: 全国営業会議・販売実績 | V4: — | W4: — | X4: — | Y4: 経営報告 | Z4: 営政, 全営 | AA4: — | AB4: — | AC4: — | AD4: 3月販売実績 | AE4: ・菓子計にはスナック・開発・飲料含む（３月販売実績）とあり、５品目計の合計範囲要確認 | AL4: e
B5: =ROW()-3 -> 2 | K5: C_ロッテ用語 | L5: 02_営業 | O5: セルオフ | P5: セルオフ | Q5: セルオフ, CA期間, 出荷期限・店頭期限 | R5: 旧品番から新品番への切替時や終売時に設定する出荷・店頭販売の期限管理。開発計画表に「セルオフ期間」「出荷期限」「店頭期限」として記載される。旧在庫を計画的に消化するための管理指標。 | T5: — | U5: — | V5: 新製品・リフレッシュ開発計画表（品番切替管理） | W5: — | X5: 生販在計画での旧/新品番の切替管理 | Y5: — | Z5: — | AA5: 新製品開発計画, チョコ定例帳票 | AB5: — | AC5: 月末事前チョコ | AD5: — | AL5: e
B6: =ROW()-3 -> 3 | C6: ○ | K6: C_ロッテ用語 | L6: 02_営業 | O6: CVS | P6: CVS | Q6: コンビニ | R6: コンビニエンスストア。50-250㎡前後で14時間以上営業。 | T6: — | U6: 全営業帳票 | V6: — | W6: — | X6: 月次市況 | Y6: — | Z6: 菓初, 全営 | AA6: — | AB6: — | AC6: 月次市況3月 | AD6: — | AH6: 1 | AI6: 下の画像にある区分で管理 | AL6: e
B7: =ROW()-3 -> 4 | C7: ○ | K7: C_ロッテ用語 | L7: 02_営業 | O7: DRUG | P7: DRUG | Q7: ドラッグストア、DgS | R7: 薬品・ヘルスケア・ビューティ売上構成比50%以上の小売業。 | T7: — | U7: 全営業帳票 | V7: — | W7: — | X7: 月次市況 | Y7: — | Z7: 菓初, 営政 | AA7: — | AB7: — | AC7: 月次市況3月 | AD7: — | AH7: 1 | AL7: e
B8: =ROW()-3 -> 5 | C8: ○ | K8: C_ロッテ用語 | L8: 02_営業 | O8: DS | P8: DS | Q8: ディスカウントストア | R8: 薄利多売を戦略とする業態。 | T8: — | U8: 営業政策 | V8: — | W8: — | X8: — | Y8: — | Z8: 営政 | AA8: — | AB8: — | AC8: — | AD8: — | AH8: 1 | AL8: e
B9: =ROW()-3 -> 6 | C9: ○ | K9: C_ロッテ用語 | L9: 02_営業 | O9: EC | P9: EC | Q9: — | R9: ネット通販。コロナ禍で利用率伸長。 | T9: — | U9: 菓子はじめて | V9: — | W9: — | X9: — | Y9: — | Z9: 菓初 | AA9: — | AB9: — | AC9: — | AD9: — | AL9: e
B10: =ROW()-3 -> 7 | C10: ○ | K10: C_ロッテ用語 | L10: 02_営業 | O10: GMS | P10: GMS | Q10: 総合スーパー | R10: 総合スーパーマーケット。食料品・衣料品・生活用品を扱う。 | T10: — | U10: 菓子はじめて | V10: — | W10: — | X10: — | Y10: — | Z10: 菓初 | AA10: — | AB10: — | AC10: — | AD10: — | AL10: e
B11: =ROW()-3 -> 8 | C11: ○ | K11: C_ロッテ用語 | L11: 02_営業 | O11: HC | P11: HC | Q11: ホームセンター | R11: ホームセンターチャネル。タスクフォース対象（カインズ・DCM・島忠・コメリ・ジョイフル本田）。 | T11: — | U11: 営業政策 | V11: — | W11: — | X11: — | Y11: — | Z11: 営政 | AA11: — | AB11: — | AC11: — | AD11: — | AL11: e
B12: =ROW()-3 -> 9 | C12: ○ | K12: C_ロッテ用語 | L12: 02_営業 | O12: JAN | P12: JAN | Q12: JANコード | R12: 日本商品コード。 | S12: 13桁 | T12: コード | U12: 全商品マスタ | V12: — | W12: — | X12: — | Y12: — | Z12: 営政, TN | AA12: — | AB12: — | AC12: — | AD12: — | AL12: e
B13: =ROW()-3 -> 10 | C13: ○ | K13: C_ロッテ用語 | L13: 02_営業 | O13: SM | P13: SM | Q13: スーパー | R13: スーパーマーケット。生鮮の扱いが強く、商品売上構成比50%以上。 | T13: — | U13: 全営業帳票 | V13: — | W13: — | X13: 月次市況 | Y13: — | Z13: 菓初, 営政 | AA13: — | AB13: — | AC13: 月次市況3月 | AD13: — | AL13: e
B14: =ROW()-3 -> 11 | K14: C_ロッテ用語 | L14: 02_営業 | O14: SM大型店 | P14: SM大型店 | Q14: — | R14: SM のうち SRI区分で1000㎡以上の店舗。 | S14: 売場面積1000㎡以上 | T14: — | U14: 営業政策, 主要商品KPI | V14: — | W14: — | X14: — | Y14: — | Z14: 営政 | AA14: — | AB14: — | AC14: — | AD14: — | AL14: e
B15: =ROW()-3 -> 12 | K15: C_ロッテ用語 | L15: 02_営業 | O15: SM中・小型店 | P15: SM中・小型店 | Q15: — | R15: SM のうち SRI区分で1000㎡以下の店舗。 | S15: 売場面積1000㎡以下 | T15: — | U15: 営業政策 | V15: — | W15: — | X15: — | Y15: — | Z15: 営政 | AA15: — | AB15: — | AC15: — | AD15: — | AL15: e
B16: =ROW()-3 -> 13 | K16: C_ロッテ用語 | L16: 02_営業 | O16: 未開拓小売業 | P16: 未開拓小売業 | Q16: ー | T16: 企業 | U16: — | V16: — | W16: — | X16: — | Y16: 本部KPI | Z16: — | AA16: — | AB16: — | AC16: — | AD16: 本部KPI確認 | AL16: e
B17: =ROW()-3 -> 14 | K17: C_ロッテ用語 | L17: 02_営業 | O17: 企業店舗コード | P17: 企業店舗コード | Q17: — | R17: 実績管理する小売業店舗コード。 | S17: 8始まりの8桁 | T17: コード | U17: 店出システム | V17: — | W17: — | X17: — | Y17: — | Z17: 推進M, 菓初 | AA17: — | AB17: — | AC17: — | AD17: — | AL17: e
B18: =ROW()-3 -> 15 | K18: C_ロッテ用語 | L18: 02_営業 | O18: 企業法人コード | P18: 企業法人コード | Q18: — | R18: 実績管理する大元の企業（小売業）法人コード。 | S18: 7始まりの8桁 | T18: コード | U18: WebPerformer, 店出システム | V18: — | W18: — | X18: — | Y18: — | Z18: 推進M, 菓初 | AA18: — | AB18: — | AC18: — | AD18: — | AL18: e
B19: =ROW()-3 -> 16 | K19: C_ロッテ用語 | L19: 02_営業 | O19: 直送店 | P19: 直送店 | Q19: — | R19: 特約店付随の卸（小売業専用・特売・冷温センター等）。 | S19: 5始まりの8桁 | T19: コード | U19: WebPerformer | V19: — | W19: — | X19: — | Y19: — | Z19: 推進M, 菓初 | AA19: — | AB19: — | AC19: — | AD19: — | AL19: e
B20: =ROW()-3 -> 17 | K20: C_ロッテ用語 | L20: 02_営業 | O20: 特約店 | P20: 特約店 | Q20: — | R20: ロッテが直接お金のやり取りをする卸店。約280企業（菓子、社内口座除く）。 | S20: 売上30百万以上、信用評価D以上 等の基準 | T20: — | U20: 特約店マスタ | V20: — | W20: — | X20: — | Y20: — | Z20: 推進M, 菓初 | AA20: — | AB20: — | AC20: — | AD20: — | AL20: e
B21: =ROW()-3 -> 18 | K21: C_ロッテ用語 | L21: 02_営業 | O21: 二次店 | P21: 二次店 | Q21: — | R21: 特約店経由で取引する卸。請求・支払は特約店経由。 | T21: — | U21: 卸マスタ | V21: — | W21: — | X21: — | Y21: — | Z21: 推進M, 菓初 | AA21: — | AB21: — | AC21: — | AD21: — | AL21: e
B22: =ROW()-3 -> 19 | K22: C_ロッテ用語 | L22: 02_営業 | O22: 1/2許容（賞味期限） | P22: 1/2許容（賞味期限） | Q22: — | R22: 賞味期限の残存が1/2を切った製品でも受け入れを許容する得意先条件。通常は個別商談・重点企業との合意が必要。 | T22: — | U22: — | V22: — | W22: — | X22: 受注管理・物流管理 | Y22: — | Z22: — | AA22: — | AB22: — | AC22: 生販物流KO②, プロテイン質問 | AD22: — | AL22: e
B23: =ROW()-3 -> 20 | K23: C_ロッテ用語 | L23: 02_営業 | O23: 1/3ルール | P23: 1/3ルール | Q23: — | R23: 卸・小売業が製品を受け入れる際に要求する賞味期限残存条件の一つ。賞味期限の2/3以上残っていることを納品条件とするルール。例：賞味期限24か月商品では残存16か月以上必要。 | T23: — | U23: — | V23: — | W23: — | X23: 受注管理・物流管理 | Y23: — | Z23: — | AA23: — | AB23: — | AC23: 生販物流KO | AD23: — | AL23: e
B24: =ROW()-3 -> 21 | K24: C_ロッテ用語 | L24: 02_営業 | O24: FMS | P24: FMS | Q24: ラウンダー | R24: 業務委託の店頭ラウンダー（株式会社フィールドマーケティングシステムズ）。 | T24: — | U24: ドラッグ12企業フォロー | V24: — | W24: — | X24: — | Y24: — | Z24: 菓初 | AA24: — | AB24: — | AC24: — | AD24: — | AL24: e
B25: =ROW()-3 -> 22 | K25: C_ロッテ用語 | L25: 02_営業 | O25: HDからのシェア奪取 | P25: HDからのシェア奪取 | Q25: HD奪取 | R25: ハーゲンダッツ（HD）が2025年に大幅な価格改定を実施したことに伴い、プレミアムアイス市場でハーゲンダッツから消費者を取り込む戦略。「アジアに恋して」等のデイリープレミアム商品で対応。 | T25: — | U25: アイスプレミアム市場戦略, 得意先商談 | V25: — | W25: — | X25: — | Y25: — | Z25: 全営 | AA25: — | AB25: — | AC25: — | AD25: — | AL25: e
B26: =ROW()-3 -> 23 | K26: C_ロッテ用語 | L26: 02_営業 | O26: LP | P26: LP | Q26: ロッテプロパー | R26: ロッテの直接雇用販売員。担当店舗を定期巡回。 | T26: — | U26: 店舗フォロー | V26: — | W26: — | X26: — | Y26: — | Z26: 菓初, 推進M | AA26: — | AB26: — | AC26: — | AD26: — | AL26: e
B27: =ROW()-3 -> 24 | K27: C_ロッテ用語 | L27: 02_営業 | O27: LP活動カレンダー | P27: LP活動カレンダー | Q27: LPカレンダー | R27: ロッテプロパー（LP）の月次活動テーマと重点取り組み商品をスケジュール化したカレンダー。年度ごとに策定され、母の日・歯と口の健康週間・爽/クーリッシュ・キシリトール等の季節テーマを設定。「噛むチャレ」は通年テーマとして別途設定される。 | T27: — | U27: LP活動管理, 売場開発年間計画 | V27: — | W27: — | X27: — | Y27: — | Z27: 全営 | AA27: — | AB27: — | AC27: — | AD27: — | AL27: e
B28: =ROW()-3 -> 25 | K28: C_ロッテ用語 | L28: 02_営業 | O28: MD | P28: MD | Q28: マーチャンダイザー | R28: 得意先側の商品担当者。バイヤーと並ぶ商談相手。 | T28: — | U28: タイムリーナレッジ | V28: — | W28: — | X28: — | Y28: — | Z28: TN | AA28: — | AB28: — | AC28: — | AD28: — | AL28: e
B29: =ROW()-3 -> 26 | C29: ○ | K29: C_ロッテ用語 | L29: 02_営業 | O29: NB | P29: NB | Q29: — | R29: NB＝National Brand（メーカーブランド）。 | T29: — | U29: 営業政策（チョコチャネル戦略） | V29: — | W29: — | X29: VC改革 | Y29: — | Z29: 営政 | AA29: — | AB29: — | AC29: 第3回SCM会議 | AD29: — | AL29: e
B30: =ROW()-3 -> 27 | C30: ○ | K30: C_ロッテ用語 | L30: 02_営業 | O30: PB | P30: PB | Q30: — | R30: PB＝Private Brand（小売業固有商品）。 | T30: — | U30: 営業政策（チョコチャネル戦略） | V30: — | W30: — | X30: VC改革 | Y30: — | Z30: 営政 | AA30: — | AB30: — | AC30: 第3回SCM会議 | AD30: — | AL30: e
B31: =ROW()-3 -> 28 | K31: C_ロッテ用語 | L31: 02_営業 | O31: PF企業 | P31: PF企業 | Q31: PF, ポートフォリオ企業 | R31: 重点取引先。Anaplan入力必須、タイムリーナレッジ入力必須対象。セグメント予算率の基礎。 | S31: セルイン予算率ベースで選定 | T31: — | U31: Anaplan, アクションプラン, タイムリーナレッジ | V31: — | W31: — | X31: — | Y31: — | Z31: TN, 推進M, 営政 | AA31: — | AB31: — | AC31: — | AD31: — | AL31: e
B32: =ROW()-3 -> 29 | K32: C_ロッテ用語 | L32: 02_営業 | O32: アイス取引制度 | P32: アイス取引制度 | Q32: 新仕切制度 | R32: 2021年度に改正されたアイスクリームの取引制度。建値制度の見直し・割戻制度廃止・新仕切価格設定・卸店対策改正・値差補填改正・フィ新基準設定を含む包括的な制度。 | T32: — | U32: アイス商談・取引制度管理 | V32: — | W32: — | X32: — | Y32: — | Z32: 氷初 | AA32: — | AB32: — | AC32: — | AD32: — | AL32: e
B33: =ROW()-3 -> 30 | K33: C_ロッテ用語 | L33: 02_営業 | O33: いい歯の日・歯と口の健康週間 | P33: いい歯の日・歯と口の健康週間 | Q33: いい歯の日 | R33: 11月8日「いい歯の日」および6月の「歯と口の健康週間」（4〜10日）。キシリトールブランドの最大訴求機会として、キシリトール最大展開・いい歯の日キャンペーン等の施策を集中投下する時期。 | T33: — | U33: キシリトール施策最大化, 店頭展開, 売場増設取組み | V33: — | W33: — | X33: — | Y33: — | Z33: 全営, 営政 | AA33: — | AB33: — | AC33: — | AD33: — | AL33: e
B34: =ROW()-3 -> 31 | K34: C_ロッテ用語 | L34: 02_営業 | O34: いもくりフェア | P34: いもくりフェア | Q34: いもくり催事 | R34: お盆明けの8月下旬〜10月頃にかけて実施される、さつまいも・栗フレーバー商品を集めた季節催事。スーパーやコンビニ各社が一斉にいもくりフェアを開催し、ロッテもチョコパイプレミアム・プレミアムガーナ等で対応する。 | T34: — | U34: いもくり催事売場獲得・陳列提案 | V34: — | W34: — | X34: — | Y34: — | Z34: 営政 | AA34: — | AB34: — | AC34: — | AD34: — | AL34: e
B35: =ROW()-3 -> 32 | K35: C_ロッテ用語 | L35: 02_営業 | O35: インバウンド需要 | P35: インバウンド需要 | Q35: インバウンド | R35: 訪日外国人観光客による国内消費需要。ドンキホーテ等の免税対応店舗での売場獲得・販促費投下の対象として管理される。菓子・アイスともにインバウンド対応強化が2026年度施策の一つ。 | T35: 円 | U35: 営業政策（特売費運用・インバウンド売場）, タイムリーナレッジ（インバウンド向け商材提案） | V35: — | W35: — | X35: — | Y35: — | Z35: 営政, TN | AA35: — | AB35: — | AC35: — | AD35: — | AL35: e
B36: =ROW()-3 -> 33 | K36: C_ロッテ用語 | L36: 02_営業 | O36: エリア重点施策 | P36: エリア重点施策 | Q36: エリア重点施策枠 | R36: 菓子7-8月・アイス11-12月の年2期間、統括支店が独自テーマ・対象商品・目標値を設定できる販売施策枠。本社統一対策とは別に統括支店の裁量で取り組みを立案できる。営業評価（統括支店組織評価）に加点項目として反映される。 | T36: — | U36: 統括支店施策立案・倉入/店出目標設定・エリア重点施策申請書 | V36: — | W36: — | X36: — | Y36: — | Z36: 営政 | AA36: — | AB36: — | AC36: — | AD36: — | AL36: e
B37: =ROW()-3 -> 34 | K37: C_ロッテ用語 | L37: 02_営業 | O37: エンカレッジ | P37: エンカレッジ | Q37: encourage | R37: 受注管理部またはアイス部門での奨励・推進活動。主に得意先や社内向けの販促・目標達成促進活動。 | T37: — | U37: — | V37: — | W37: — | X37: 受注管理・販促活動 | Y37: — | Z37: — | AA37: — | AB37: — | AC37: アイスエンカレ | AD37: — | AL37: e
B38: =ROW()-3 -> 35 | K38: C_ロッテ用語 | L38: 02_営業 | O38: エンジョイハロウィン | P38: エンジョイハロウィン | Q38: エンジョイHW, ハロウィン限定商品 | R38: ロッテのハロウィン季節限定商品ライン。2026年テーマは「ENJOY 黒（ブラック）HALLOWEEN！」で、新キャラ「コアラのニャーチ」を起用したコアラのマーチ・パイの実・チョコパイのシェアパック・パーティーパックを展開。 | T38: 円 | U38: ハロウィン催事提案・売場陳列・シェアパック提案 | V38: — | W38: — | X38: — | Y38: — | Z38: 営政 | AA38: — | AB38: — | AC38: — | AD38: — | AL38: e
B39: =ROW()-3 -> 36 | K39: C_ロッテ用語 | L39: 02_営業 | O39: エンド | P39: エンド | Q39: エンド展開 | R39: 店頭の什器の端（エンド）への商品展開。 | T39: — | U39: 商談, 店頭展開 | V39: — | W39: — | X39: — | Y39: — | Z39: 菓初, TN | AA39: — | AB39: — | AC39: — | AD39: — | AL39: e
B40: =ROW()-3 -> 37 | K40: C_ロッテ用語 | L40: 02_営業 | O40: キット | P40: キット | Q40: ディスプレイ | R40: 店頭での販促資材。ショッパー接点増加に寄与。 | T40: — | U40: SPinno, 営業活動 | V40: — | W40: — | X40: — | Y40: — | Z40: 菓初 | AA40: — | AB40: — | AC40: — | AD40: — | AL40: e
B41: =ROW()-3 -> 38 | K41: C_ロッテ用語 | L41: 02_営業 | O41: キット展開 | P41: キット展開 | Q41: — | R41: キット販促を展開すること。市場前比に対するキット展開企業の前比効果を測定。 | T41: — | U41: 営業活動 | V41: — | W41: — | X41: — | Y41: — | Z41: 菓初 | AA41: — | AB41: — | AC41: — | AD41: — | AL41: e
...

Sheet 99_区分マスタ
I1: e
I2: e
B3: 指標大分類 | C3: ※注 | D3: 指標タイプLv.1 | E3: ※注 | F3: 指標タイプLv.2 | G3: ※注 | H3: 指標タイプLv.3 | I3: e
B4: A_指標 | D4: 01_財務指標 | E4: 各種項目一覧 | F4: 01_PL | H4: 売上高 | I4: e
B5: A_指標 | D5: 01_財務指標 | F5: 01_PL | H5: 売上控除 | I5: e
B6: A_指標 | D6: 01_財務指標 | F6: 01_PL | H6: 売上原価 | I6: e
B7: A_指標 | D7: 01_財務指標 | F7: 01_PL | H7: 販管費 | I7: e
B8: A_指標 | D8: 01_財務指標 | F8: 01_PL | H8: 利益・損失 | I8: e
B9: A_指標 | D9: 01_財務指標 | F9: 02_BS | H9: 資産 | I9: e
B10: A_指標 | D10: 01_財務指標 | F10: 02_BS | H10: 負債 | I10: e
B11: A_指標 | D11: 01_財務指標 | F11: 03_CF | G11: 該当なし | I11: e
B12: A_指標 | D12: 02_業績管理・オペレーション指標 | E12: 部門KPIや日々業務で発生する数字 | F12: 01_商品開発 | H12: 利益項目 | I12: e
B13: A_指標 | D13: 02_業績管理・オペレーション指標 | F13: 01_商品開発 | H13: その他 | I13: e
B14: A_指標 | D14: 02_業績管理・オペレーション指標 | F14: 02_生販在 | H14: 生産 | I14: e
B15: A_指標 | D15: 02_業績管理・オペレーション指標 | F15: 02_生販在 | H15: 販売 | I15: e
B16: A_指標 | D16: 02_業績管理・オペレーション指標 | F16: 02_生販在 | H16: 在庫 | I16: e
B17: A_指標 | D17: 02_業績管理・オペレーション指標 | F17: 03_商品製造 | H17: 収益性 | I17: e
B18: A_指標 | D18: 02_業績管理・オペレーション指標 | F18: 03_商品製造 | H18: 生産性 | I18: e
B19: A_指標 | D19: 02_業績管理・オペレーション指標 | F19: 03_商品製造 | H19: 品質 | I19: e
B20: A_指標 | D20: 02_業績管理・オペレーション指標 | F20: 03_商品製造 | H20: 労務 | I20: e
B21: A_指標 | D21: 02_業績管理・オペレーション指標 | F21: 04_販売 | H21: 特売費項目 | I21: e
B22: A_指標 | D22: 02_業績管理・オペレーション指標 | F22: 04_販売 | H22: フィ項目 | I22: e
B23: A_指標 | D23: 02_業績管理・オペレーション指標 | F23: 04_販売 | H23: LP管理 | I23: e
B24: A_指標 | D24: 02_業績管理・オペレーション指標 | F24: 04_販売 | H24: 販売価格 | I24: e
... B36: A_指標 | D36: 02_業績管理・オペレーション指標 | F36: 06_コーポレート | H36: 非財務 | I36: e
B37: A_指標 | D37: 03_その他 | F37: - | I37: e
B38: B_マスタ | D38: 01_商品・ブランドマスタ | E38: 各種システムでマスタ扱いされているもの | I38: e
B39: B_マスタ | D39: 02_製造ラインマスタ | E39: （SAP 等） | I39: e
B40: B_マスタ | D40: 03_得意先マスタ | I40: e
B41: B_マスタ | D41: 04_プラントマスタ | I41: e
B42: B_マスタ | D42: 05_組織マスタ | I42: e
B43: B_マスタ | D43: 06_その他マスタ | I43: e
B44: C_ロッテ用語 | C44: 単純な用語の説明 | D44: 01_全社 | I44: e
B45: C_ロッテ用語 | D45: 02_営業 | I45: e
B46: C_ロッテ用語 | D46: 03_SCM | I46: e
B47: C_ロッテ用語 | D47: 04_生産 | I47: e
B48: C_ロッテ用語 | D48: 05_マーケ・研究 | I48: e
B49: C_ロッテ用語 | D49: 06_コーポレート | I49: e
B50: C_ロッテ用語 | D50: 07_その他 | I50: e
B51: e | C51: e | D51: e | E51: e | F51: e | G51: e | H51: e | I51: e

Sheet 出典
A1: 出典マスタ — ロッテグループ標準言語定義辞書 | E1: e
A2: 列の順序：①部門区分 ②略称（辞書の出典欄で使用する短縮形） ③正式名称 | E2: e
A3: ①部門区分 | B3: ②略称 | C3: ③正式名称／ファイル名 | D3: 備考 | E3: e
A4: SCM | B4: 臼井T | C4: 臼井さん_タスク一覧.xlsx | D4: SCMDX推進課のツール開発タスク管理表 | E4: e
A5: SCM | B5: SCM大会 | C5: 【投影】SCM大会260420.pptx | D5: 2026年4月SCM大会の投影資料 | E5: e
A6: SCM | B6: SCM会議 | C6: 20260316SCM会議資料.pptx | D6: 同名のpdfも同一資料 | E6: e
A7: SCM | B7: SCM本部会議 | C7: SCM本部会議_エグゼクティブサマリ_260424.pptx | D7: 2026年4月SCM本部会議エグゼクティブサマリ | E7: e
A8: SCM | B8: SCM戦略MTG | C8: 20260430SCM戦略部MTG.pptx | D8: 2026年4月SCM戦略部MTG資料 | E8: e
A9: SCM | B9: 月次報 | C9: ３月月次報告.pptx | D9: SCM需給部の欠品率・D+2締め率月次報告 | E9: e
A10: SCM | B10: 生販会議 | C10: 4月SCM生販会議資料_.pptx | D10: SCM需給部の販売振り返り・見込資料 | E10: e
A11: SCM | B11: 振返アイス | C11: アイス_3月度_販売振り返りミーティング.xlsx | D11: アイス3月度品目別販売振り返り | E11: e
A12: SCM | B12: 振返ガム | C12: ガム_2603_販売振り返りミーティング.xlsx | D12: ガム3月度品目別販売振り返り | E12: e
A13: SCM | B13: 振返キャン | C13: キャンディ_3月度_振り返りミーティング.xlsx | D13: キャンディ3月度品目別販売振り返り | E13: e
A14: SCM | B14: 振返チョコ | C14: チョコ_3月度_販売振り返りミーティング.xlsx | D14: チョコ3月度品目別販売振り返り | E14: e
... A21: SCM | B21: 月末事前チョコ | C21: ☆【0420】チョコレート長期数表生販在表（26年4月月末生販会議前）.xlsx さ☆【0420】チョコレート長期数表生販在表（26年4月月末生販会議前）.xlsx | D21: チョコレート長期数表生販在表。月末調整事前会議（2026/4/20）用。 | E21: e
A22: SCM | B22: 協力チョコ | C22: 協力☆【0423チョコ協力】チョコレート長期数表生販在表（26年4月月末生販会議前）.xlsx | E22: e
A23: SCM | B23: 滋賀チョコ | C23: 滋賀☆【0420】チョコレート長期数表生販在表（26年4月月末生販会議前）.xlsx | E23: e
A24: SCM | B24: 滋賀菓子工程 | C24: 滋賀菓子工程4-6月（４月月末会議）.xlsx | E24: e
A25: SCM | B25: KYチョコ | C25: ｋｙ☆【0420】チョコレート長期数表生販在表（26年4月月末生販会議前・九州工場案）.xlsx | E25: e
A26: SCM | B26: ローテ | C26: ﾛｰﾃｰｼｮﾝ(4月生販会議前) .xlsx | E26: e
A27: SCM | B27: 月末会議キャン | C27: 202604キャンディ月末会議資料.xlsx | D27: キャンディ2026年度生販在計画（月末調整会議版）。 | E27: e
A28: SCM | B28: 月末会議ビス | C28: 202604ビスケット月末生販会議前.xlsx | D28: ビスケット生販在計画（月末調整会議版）。 | E28: e
A29: SCM | B29: 月末会議ガム | C29: ガム25年度長期計画(4月月末会議資料).xlsx | D29: ガム生販在計画（月末調整会議版）。 | E29: e
A30: SCM | B30: 工程狭山 | C30: ●2604狭山月末生販前★確定版★2026年度ビスケットチョコ工程.xlsx | D30: 狭山工場2026年度ビスケット・チョコ月間工程表。 | E30: e
A31: SCM | B31: 工程九州菓子 | C31: ●2604九州月末生販前0420２５菓子・アイス月間工程.xlsx | D31: 九州工場菓子・アイス月間工程表（2026/4/20版）。 | E31: e
A32: SCM | B32: 工程浦和アイス業 | C32: 浦和アイス月間工程（業務用）4-6.xlsx | D32: 浦和工場アイス月次工程表（業務用）4〜6月。 | E32: e
A33: SCM | B33: 工程浦和アイス市 | C33: 浦和アイス月間工程（市販用）4-6.xlsx | D33: 浦和工場アイス月次工程表（市販用）4〜6月。 | E33: e
A34: SCM | B34: 工程九州アイス | C34: 九州アイス月間工程4-6.xlsx | D34: 九州工場アイス月間工程表4〜6月。 | E34: e
A35: SCM | B35: 工程滋賀アイス | C35: 滋賀アイス工程4-6月.xlsx | D35: 滋賀工場アイス月間工程表4〜6月。 | E35: e
A36: SCM | B36: 工程滋賀菓子 | C36: 滋賀菓子工程4-6月（４月月末会議）.xlsx | D36: 滋賀工場菓子月間工程表4〜6月（月末会議版）。 | E36: e
A37: SCM | B37: 菓子アイス月間 | C37: 0427予定２５菓子・アイス月間工程 - コピー.xlsx | E37: e
A38: SCM | B38: 支払報告需給 | C38: 2026.04支払い報告資料（需給部） .pptx | D38: 4月度支払い報告（需給部）：販売状況・在庫状況・滞貨状況。 | E38: e
A39: SCM | B39: 物流費報告 | C39: 物流費報告（26.04).pptx | D39: 4月度物流費報告：一次輸送・二次配送・保管料・廃棄焼却申請。 | E39: e
A40: SCM | B40: 生販会議生産 | C40: 26年4月生販会議（生産管理課） .pptx | D40: SCM需給部生産管理課の生販情報共有会議資料。在庫・滞貨・欠品率推移。 | E40: e
A41: SCM | B41: STS定例 | C41: STS_改修週次定例_20260428.pptx | D41: SCMシステム（STS）の改修・保守課題進捗の週次定例資料。 | E41: e
A42: SCM | B42: 物流企画一課 | C42: 26年4月度SCM会議資料（物流企画一課）.pptx | D42: 物流部物流企画一課の4月SCM本部会議資料。物流費・生販在計画。 | E42: e
A43: SCM | B43: 第3回SCM議事録 | C43: 20260316_第3回SCM会議 議事録.docx | D43: 2026年3月16日開催SCM会議（第3回）の議事録。物流効率化法・生販在PSI計画・VC改革を議論。 | E43: e
A44: SCM | B44: 第1回SCM議事録 | C44: 【参考】20250512_SCM会議 議事録.docx | D44: 2025年5月12日開催SCM会議（第1回）の議事録。SCM会議立ち上げ・限界利益領域・欠品時意思決定ケーススタディ。 | E44: e
A45: SCM | B45: 第2回SCM議事録 | C45: 【参考】20250828_第2回SCM会議 議事録.docx | D45: 2025年8月28日開催SCM会議（第2回）の議事録。夏季アイス販売・特売費コントロール・在庫適正化を議論。 | E45: e
A46: SCM | B46: SCM本部（SCM戦略部・受注管理部・需給部・物流部・SCMDX推進課） | E46: e
...

Sheet >0604

Sheet 依頼内容
A1: ロッテグループ標準言語定義辞書化プロジェクト 作業依頼
A3: 1 | B3: 対象資料は出典シートに記載されている資料とする。ロッテの業績管理指標に関する用語・算出式・定義を中心に用語を抽出する。
A4: 2 | B4: 用語辞書シートのG列（定義）、H列（算出式/構造）、I列（単位）を確認し、誤りがある場合は以下の通り対応する。
B6: W列（フラグ）に「1」を記載する。
B7: X列（修正後の定義）、Y列（修正後の算出式/構造）、Z列（修正後の単位）に修正後の内容を記載する。
B8: 修正後欄に記載がある場合はその内容を正として上書きするため、修正後の全文を記載すること。修正が必要なX・Y・Z列のみ記載すれば良い。
A10: 3 | B10: T列（備考）および赤文字・黄色ハイライト箇所は特に確認が必要な箇所であるため、列（備考）とあわせて確認する。
B11: T列（備考）および赤文字・黄色ハイライト箇所は特に確認が必要な箇所であるため、T列（備考）とあわせて確認する。
A12: 4 | B12: 追記したい用語がある場合は、B列（指標大分類）、C列（指標タイプ）、D列（概念）、E列（用語）に内容を記載したうえで、
B13: W列（フラグ）に「1」を記載し、X列（修正後の定義）、Y列（修正後の算出式/構造）、Z列（修正後の単位）に定義を記載する。
D47: スマートファクトリー化計画進捗度

Sheet 0604FB_用語辞書
A1: No | B1: 経営ダッシュボード | C1: 確認部門 | D1: 分科① | E1: 分科② | F1: 分科③ | G1: 分科④ | H1: 分科⑤ | I1: 分科⑥ | J1: 指標大分類 | K1: 指標タイプ | L1: 概念 | M1: 用語 | N1: 略称/同義語 | O1: 定義 | P1: 算出式 / 構造 | Q1: 単位 | R1: 使用シーン / 主な帳票 | W1: 出典 | AE1: 要修正フラグ | AF1: 修正後 | AI1: e
R2: 営業 | S2: マーケ | T2: 生産 | U2: SCM | V2: 経営戦略 ・収益企画 | W2: 営業 | X2: マーケ | Y2: 生産 | Z2: SCM | AA2: 経営戦略 ・収益企画 | AB2: 備考 | AC2: 確認対象部門 | AD2: 収益企画部担当者 | AE2: ドラフトに誤りがある場合1を記載 | AF2: 定義 | AG2: 算出式 / 構造 | AH2: 単位 | AI2: e
A3: =ROW()-2 -> 1 | J3: 01_指標 | K3: =_xlfn.XLOOKUP(L3,'99_マスタ'!$D$5:$D$18,'99_マスタ'!$C$5:$C$18,"") -> 01_財務・業績指標 | L3: 01_売上 | M3: 売上 | N3: メーカー別売上、販売額 | O3: メーカー別の推定売上高。海外売上および内部取引を控除した国内市販用の販売金額。各月の着地（実績確定）ベースで集計され、月次および年度累計（4月〜3月）で管理される。 | P3: 推定売上高 − 海外売上 − 内部取引額 | Q3: 円 | R3: — | S3: マーケットシェア分析 | T3: — | U3: — | V3: — | W3: — | X3: プランニング実績,損益共有MTG,マーケ生販会議 | Y3: — | Z3: — | AA3: — | AI3: e
A4: =ROW()-2 -> 2 | J4: 01_指標 | K4: =_xlfn.XLOOKUP(L4,'99_マスタ'!$D$5:$D$18,'99_マスタ'!$C$5:$C$18,"") -> 01_財務・業績指標 | L4: 01_売上 | M4: 売上 | N4: 売上高 | O4: 純売上高を売上高として記載 | Q4: 円 | R4: — | S4: — | T4: — | U4: — | V4: KK定例会長報告 | W4: — | X4: — | Y4: — | Z4: — | AA4: KK定例会長報告 | AI4: e
A5: =ROW()-2 -> 3 | J5: 01_指標 | K5: =_xlfn.XLOOKUP(L5,'99_マスタ'!$D$5:$D$18,'99_マスタ'!$C$5:$C$18,"") -> 01_財務・業績指標 | L5: 01_売上 | M5: 売上（控除前） | N5: ー | O5: 売上控除項目（年契リベート・販促協賛金等の取引先への割戻し）を差し引く前の売上高。事業損益表において各種比率（特売費率・販売費計率等）の分母として使用される基準売上。控除後の純売上高とは異なり、割戻し前の総額ベースの売上を示す | P5: 純売上高 ＋ 売上控除額（年契・協賛金等） | Q5: 円 | R5: 事業損益 | S5: — | T5: — | U5: — | V5: — | W5: 全営 | X5: — | Y5: — | Z5: — | AA5: — | AI5: e
A6: =ROW()-2 -> 4 | J6: 01_指標 | K6: =_xlfn.XLOOKUP(L6,'99_マスタ'!$D$5:$D$18,'99_マスタ'!$C$5:$C$18,"") -> 01_財務・業績指標 | L6: 01_売上 | M6: 売上控除 | N6: 控除 | O6: 総売上高から差し引かれる控除項目の合計。主に特売費（控除対象）が含まれる。純売上高＝総売上高−売上控除。 | P6: 総売上高 − 純売上高 | Q6: 円 | R6: — | S6: — | T6: — | U6: — | V6: 損益計算書（P/L） | W6: — | X6: — | Y6: — | Z6: — | AA6: 2月個別決算, 3月販売実績 | AI6: e
A7: =ROW()-2 -> 5 | J7: 01_指標 | K7: =_xlfn.XLOOKUP(L7,'99_マスタ'!$D$5:$D$18,'99_マスタ'!$C$5:$C$18,"") -> 01_財務・業績指標 | L7: 01_売上 | M7: 一人当たり売上額 | N7: — | O7: 生産性指標。正社員、臨時社員合計の一人当たり売上額 | Q7: 円 | R7: — | S7: — | T7: — | U7: — | V7: KK定例会長報告 | W7: — | X7: — | Y7: — | Z7: — | AA7: KK定例会長報告 | AB7: ・算出式要確認 | AI7: e
A8: =ROW()-2 -> 6 | J8: 01_指標 | K8: =_xlfn.XLOOKUP(L8,'99_マスタ'!$D$5:$D$18,'99_マスタ'!$C$5:$C$18,"") -> 01_財務・業績指標 | L8: 01_売上 | M8: 海外事業計（現地会計基準） | N8: 海外事業計 | O8: ㈱ロッテの資料では、海外現法（アジア計＋ウェデル計）の純売上高・営業利益を現地の会計基準で集計した合計。社内レートで円換算して表示。 | P8: アジア計（タイ・インドネシア・ベトナム・台湾）+ ウェデル計（ウェデル・ウェデルカフェ） | Q8: 円 | R8: — | S8: — | T8: — | U8: — | V8: 個別決算報告（海外現法） | W8: — | X8: — | Y8: — | Z8: — | AA8: 2月個別決算 | AI8: e
A9: =ROW()-2 -> 7 | J9: 01_指標 | K9: =_xlfn.XLOOKUP(L9,'99_マスタ'!$D$5:$D$18,'99_マスタ'!$C$5:$C$18,"") -> 01_財務・業績指標 | L9: 01_売上 | M9: 営業概況 | N9: ー | O9: 販売振り返りMTGで使用される営業の売上 | Q9: 円 | R9: — | S9: — | T9: — | U9: 販売実績・見込みすり合わせ | V9: — | W9: — | X9: — | Y9: — | Z9: 振返アイス,振返ガム,振返チョコ,振返キャン,振返ビス | AA9: — | AB9: ・営業概況は売上高金額のようだが、それが総売上高なのか純売上高なのか要確認 | AI9: e
A10: =ROW()-2 -> 8 | J10: 01_指標 | K10: =_xlfn.XLOOKUP(L10,'99_マスタ'!$D$5:$D$18,'99_マスタ'!$C$5:$C$18,"") -> 01_財務・業績指標 | L10: 01_売上 | M10: 概況精度 | N10: ー | O10: 統括支店が提出した概況（需要予測）の精度を示す指標。倉入実績をAnaplan倉入計画と比較し、概況提出締切日時点での「1ヵ月前」の計画値がどれだけ実績に近かったかを測る。組織評価における評価指標の一つで、菓子・アイスそれぞれウェイト10%（合計20%）で配点される。広域流通のみ「店出実績/Anaplan店出計画」を基準として算出。 | P10: 倉入実績 ÷ Anaplan倉入計画（概況提出締切日時点の1ヵ月前計画値）※広域流通は店出実績 ÷ Anaplan店出計画 | Q10: 倍 | R10: 支店別評価 | S10: — | T10: — | U10: — | V10: — | W10: 全営 | X10: — | Y10: — | Z10: — | AA10: — | AI10: e
A11: =ROW()-2 -> 9 | J11: 01_指標 | K11: =_xlfn.XLOOKUP(L11,'99_マスタ'!$D$5:$D$18,'99_マスタ'!$C$5:$C$18,"") -> 01_財務・業績指標 | L11: 01_売上 | M11: 小売店年契-基本 | N11: ー | O11: 特売費の種類の一つ。XXX（どのような特売費か要確認） | Q11: 円 | R11: — | S11: — | T11: — | U11: SCM会議（特売費適正化） | V11: — | W11: — | X11: — | Y11: — | Z11: SCM会議 | AA11: — | AI11: e
A12: =ROW()-2 -> 10 | J12: 01_指標 | K12: =_xlfn.XLOOKUP(L12,'99_マスタ'!$D$5:$D$18,'99_マスタ'!$C$5:$C$18,"") -> 01_財務・業績指標 | L12: 01_売上 | M12: 小売店年契-達成 | N12: ー | O12: 特売費の種類の一つ。XXX（どのような特売費か要確認） | R12: — | S12: — | T12: — | U12: SCM会議（特売費適正化） | V12: — | W12: — | X12: — | Y12: — | Z12: SCM会議 | AA12: — | AI12: e
A13: =ROW()-2 -> 11 | J13: 01_指標 | K13: =_xlfn.XLOOKUP(L13,'99_マスタ'!$D$5:$D$18,'99_マスタ'!$C$5:$C$18,"") -> 01_財務・業績指標 | L13: 01_売上 | M13: 資材 | N13: ー | O13: 特売費の種類の一つ。XXX（どのような特売費か要確認） | R13: — | S13: — | T13: — | U13: SCM会議（特売費適正化） | V13: — | W13: — | X13: — | Y13: — | Z13: SCM会議 | AA13: — | AI13: e
A14: =ROW()-2 -> 12 | J14: 01_指標 | K14: =_xlfn.XLOOKUP(L14,'99_マスタ'!$D$5:$D$18,'99_マスタ'!$C$5:$C$18,"") -> 01_財務・業績指標 | L14: 01_売上 | M14: 滞貨品消化 | N14: ー | O14: 特売費の種類の一つ。XXX（どのような特売費か要確認） | Q14: ー | R14: — | S14: — | T14: — | U14: SCM会議（特売費適正化） | V14: — | W14: — | X14: — | Y14: — | Z14: SCM会議 | AA14: — | AI14: e
A15: =ROW()-2 -> 13 | J15: 01_指標 | K15: =_xlfn.XLOOKUP(L15,'99_マスタ'!$D$5:$D$18,'99_マスタ'!$C$5:$C$18,"") -> 01_財務・業績指標 | L15: 01_売上 | M15: 本部協賛-その他 | N15: ー | O15: 特売費の種類の一つ。XXX（どのような特売費か要確認） | Q15: ー | R15: — | S15: — | T15: — | U15: SCM会議（特売費適正化） | V15: — | W15: — | X15: — | Y15: — | Z15: SCM会議 | AA15: — | AI15: e
A16: =ROW()-2 -> 14 | J16: 01_指標 | K16: =_xlfn.XLOOKUP(L16,'99_マスタ'!$D$5:$D$18,'99_マスタ'!$C$5:$C$18,"") -> 01_財務・業績指標 | L16: 01_売上 | M16: 本部協賛-チラシ・POP代 | N16: ー | O16: 特売費の種類の一つ。XXX（どのような特売費か要確認） | Q16: ー | R16: — | S16: — | T16: — | U16: SCM会議（特売費適正化） | V16: — | W16: — | X16: — | Y16: — | Z16: SCM会議 | AA16: — | AI16: e
A17: =ROW()-2 -> 15 | J17: 01_指標 | K17: =_xlfn.XLOOKUP(L17,'99_マスタ'!$D$5:$D$18,'99_マスタ'!$C$5:$C$18,"") -> 01_財務・業績指標 | L17: 01_売上 | M17: 本部協賛-ポイント戻 | N17: ー | O17: 特売費の種類の一つ。XXX（どのような特売費か要確認） | Q17: ー | R17: — | S17: — | T17: — | U17: SCM会議（特売費適正化） | V17: — | W17: — | X17: — | Y17: — | Z17: SCM会議 | AA17: — | AI17: e
A18: =ROW()-2 -> 16 | J18: 01_指標 | K18: =_xlfn.XLOOKUP(L18,'99_マスタ'!$D$5:$D$18,'99_マスタ'!$C$5:$C$18,"") -> 01_財務・業績指標 | L18: 01_売上 | M18: 本部協賛-本部戻 | N18: ー | O18: 特売費の種類の一つ。XXX（どのような特売費か要確認） | Q18: ー | R18: — | S18: — | T18: — | U18: SCM会議（特売費適正化） | V18: — | W18: — | X18: — | Y18: — | Z18: SCM会議 | AA18: — | AI18: e
A19: =ROW()-2 -> 17 | J19: 01_指標 | K19: =_xlfn.XLOOKUP(L19,'99_マスタ'!$D$5:$D$18,'99_マスタ'!$C$5:$C$18,"") -> 01_財務・業績指標 | L19: 01_売上 | M19: 実販対策 | N19: ー | O19: 特売費の種類の一つ。XXX（どのような特売費か要確認） | Q19: ー | R19: — | S19: — | T19: — | U19: SCM会議（特売費適正化） | V19: — | W19: — | X19: — | Y19: — | Z19: SCM会議 | AA19: — | AI19: e
A20: =ROW()-2 -> 18 | J20: 01_指標 | K20: =_xlfn.XLOOKUP(L20,'99_マスタ'!$D$5:$D$18,'99_マスタ'!$C$5:$C$18,"") -> 01_財務・業績指標 | L20: 01_売上 | M20: センターフィ | N20: ー | O20: 特売費の種類の一つ。XXX（どのような特売費か要確認） | Q20: ー | R20: — | S20: — | T20: — | U20: SCM会議（特売費適正化） | V20: — | W20: — | X20: — | Y20: — | Z20: SCM会議 | AA20: — | AI20: e
A21: =ROW()-2 -> 19 | J21: 01_指標 | K21: =_xlfn.XLOOKUP(L21,'99_マスタ'!$D$5:$D$18,'99_マスタ'!$C$5:$C$18,"") -> 01_財務・業績指標 | L21: 01_売上 | M21: 特売経費率 | N21: 特売費率（総売比） | O21: 売上に占める特売費の割合。品目別・統括支店別・ブランド別に管理し、予算比・前年比で分析する。費用の使用効率を示す指標で、売上増加と特売費削減の両立が目標。 | P21: 特売経費率 = 特売費 ÷ 売上 × 100 | Q21: % | R21: 特売費分析, 月次全国営業会議, 営業政策 | S21: — | T21: — | U21: — | V21: — | W21: 全営, 営政 | X21: — | Y21: — | Z21: — | AA21: — | AI21: e
A22: =ROW()-2 -> 20 | J22: 01_指標 | K22: =_xlfn.XLOOKUP(L22,'99_マスタ'!$D$5:$D$18,'99_マスタ'!$C$5:$C$18,"") -> 01_財務・業績指標 | L22: 01_売上 | M22: 出荷実績 | N22: ー | O22: 当該年度累計における製品の出荷金額の確定値。予算・前年実績と対比する形で管理され、カテゴリ（ガム・チョコレート・キャンディ・ビスケット・市販用アイス・業務用アイス）別および菓子計・アイス計・菓子アイス計の集計単位で把握される。 | Q22: 円 | R22: — | S22: マーケットシェア分析 | T22: — | U22: — | V22: — | W22: — | X22: プランニング実績 | Y22: — | Z22: — | AA22: — | AB22: ・売上との違い要確認 | AI22: e
A23: =ROW()-2 -> 21 | J23: 01_指標 | K23: =_xlfn.XLOOKUP(L23,'99_マスタ'!$D$5:$D$18,'99_マスタ'!$C$5:$C$18,"") -> 01_財務・業績指標 | L23: 01_売上 | M23: チャンスロス | N23: 販売機会損失 | O23: 欠品や在庫不足により本来得られたはずの売上が失われること。SCM部門の主要KPIである欠品率と連動して管理される。 | Q23: 円 | R23: — | S23: — | T23: — | U23: SCM本部KPI（チャンスロス削減） | V23: 経営会議（SCM本部KPI） | W23: — | X23: — | Y23: — | Z23: SCM本部会議全体 | AA23: 本部KPI確認 | AI23: e
A24: =ROW()-2 -> 22 | J24: 01_指標 | K24: =_xlfn.XLOOKUP(L24,'99_マスタ'!$D$5:$D$18,'99_マスタ'!$C$5:$C$18,"") -> 01_財務・業績指標 | L24: 01_売上 | M24: 販売 | N24: ー | O24: 生販在計画表における、販売量 | Q24: CS | R24: — | S24: — | T24: — | U24: 生販在計画表 | V24: — | W24: — | X24: — | Y24: — | Z24: 月末キャン | AA24: — | AB24: ・何を基準として”販売”と、みなしているのか（出荷？どこ向け？）要確認 | AI24: e
A25: =ROW()-2 -> 23 | J25: 01_指標 | K25: =_xlfn.XLOOKUP(L25,'99_マスタ'!$D$5:$D$18,'99_マスタ'!$C$5:$C$18,"") -> 01_財務・業績指標 | L25: 01_売上 | M25: 純売上高 | N25: 純売ベース、純売 | O25: 総売上から返品・値引等を控除した売上。営業利益の率計算の分母として使用される。 | P25: 総売上 − 値引・返品・販売費（一部） | Q25: 円 | R25: 品目別営業利益（純売ベース）, 営業会議資料 | S25: 新商品マーケット分析 | T25: — | U25: — | V25: 個別決算 | W25: 全営 | X25: アジア恋ナレッジ | Y25: — | Z25: — | AA25: 2月個別決算、本部KPI確認 | AI25: e
A26: =ROW()-2 -> 24 | J26: 01_指標 | K26: =_xlfn.XLOOKUP(L26,'99_マスタ'!$D$5:$D$18,'99_マスタ'!$C$5:$C$18,"") -> 01_財務・業績指標 | L26: 01_売上 | M26: 生産性 | N26: ー | O26: 工場人員一人当たりの売上金額 | Q26: 円 | R26: — | S26: — | T26: — | U26: — | V26: 本部KPI | W26: — | X26: — | Y26: — | Z26: — | AA26: 本部KPI確認 | AB26: ・生産本部が掲げる生産性には2種類存在 | AI26: e
A27: =ROW()-2 -> 25 | J27: 01_指標 | K27: =_xlfn.XLOOKUP(L27,'99_マスタ'!$D$5:$D$18,'99_マスタ'!$C$5:$C$18,"") -> 01_財務・業績指標 | L27: 01_売上 | M27: 総売上高 | N27: 総売 | O27: 控除を行っていない売上の合計額。ロッテの場合は仕切り価格販売の積み上げ | P27: 販売数量×単価（仕切価格） | Q27: 円 | R27: 全国営業会議, 営業政策, 予算表 | S27: — | T27: — | U27: 商品規格適正化検討、ロッテ業績 | V27: 個別決算 | W27: 営政, 全営 | X27: — | Y27: — | Z27: SCM会議、ロッテ業績簡易版 | AA27: 2月個別決算 | AI27: e
A28: =ROW()-2 -> 26 | J28: 01_指標 | K28: =_xlfn.XLOOKUP(L28,'99_マスタ'!$D$5:$D$18,'99_マスタ'!$C$5:$C$18,"") -> 01_財務・業績指標 | L28: 01_売上 | M28: 店出実績 | N28: 店出, 店出し | O28: 得意先（卸）から小売業（企業）への納品実績。 | P28: 卸→小売業 への納品金額。直取得意先は倉入＝店出。 | Q28: 円, CS | R28: 店出システム, BO, 月次企業計画差異 | S28: — | T28: — | U28: — | V28: — | W28: 推進M, 全営 | X28: — | Y28: — | Z28: — | AA28: — | AI28: e
A29: =ROW()-2 -> 27 | J29: 01_指標 | K29: =_xlfn.XLOOKUP(L29,'99_マスタ'!$D$5:$D$18,'99_マスタ'!$C$5:$C$18,"") -> 01_財務・業績指標 | L29: 01_売上 | M29: 特売費 | N29: — | O29: 特売実施で発生する経費全般。控除対象/控除対象外で区別。 | P29: 値差補填 + 特売条件 + 特売拡売費 等 | Q29: 円 | R29: Biz, 特売費分析 | S29: — | T29: — | U29: SCM会議（特売費コントロール・値差上限導入検討） | V29: — | W29: 営政, 全営 | X29: — | Y29: — | Z29: SCM会議, 第3回SCM議事録, 第2回SCM議事録 | AA29: — | AI29: e
A30: =ROW()-2 -> 28 | J30: 01_指標 | K30: =_xlfn.XLOOKUP(L30,'99_マスタ'!$D$5:$D$18,'99_マスタ'!$C$5:$C$18,"") -> 01_財務・業績指標 | L30: 01_売上 | M30: 特売費率 | N30: — | O30: 売上に対する特売費の比率。営業利益管理の主要KPI。 | P30: 特売費 ÷ 売上 × 100 | Q30: % | R30: 営業政策, 全営の特売費分析 | S30: 損益概況 | T30: — | U30: SCM会議 | V30: 収益企画社長報告（PLツリー：品目別特売費率管理） | W30: 営政, 全営 | X30: 損益共有MTG | Y30: — | Z30: 第2回SCM議事録 | AA30: KK定例会長報告 | AI30: e
A31: =ROW()-2 -> 29 | J31: 01_指標 | K31: =_xlfn.XLOOKUP(L31,'99_マスタ'!$D$5:$D$18,'99_マスタ'!$C$5:$C$18,"") -> 01_財務・業績指標 | L31: 01_売上 | M31: 連結売上高 | N31: 連結 | O31: ㈱ロッテおよびグループ会社を連結した売上高。経理の連結決算で使用される概念で、単体（個別）売上とは異なる。 | P31: ・単体売上高 + グループ会社売上 − 内部取引消去 ・単体売上高＋グループ会社売上ー連結修正 | Q31: 円 | R31: — | S31: — | T31: — | U31: — | V31: 個別決算報告（参照概念）、KK定例会長報告（連結決算速報：国内計・海外計・WEDEL等） | W31: — | X31: — | Y31: — | Z31: — | AA31: KK定例会長報告 | AI31: e
A32: =ROW()-2 -> 30 | J32: 01_指標 | K32: =_xlfn.XLOOKUP(L32,'99_マスタ'!$D$5:$D$18,'99_マスタ'!$C$5:$C$18,"") -> 02_生販在 | L32: 07_販売 | M32: 1か月前見込比 | N32: — | O32: 販売振り返りミーティングで使用する精度指標。1か月前に立案されたSCM見込みまたは営業概況に対する当月実績の比率。 | P32: 当月実績 ÷ 1か月前見込み × 100 | Q32: % | R32: — | S32: — | T32: — | U32: 各カテゴリ振り返りMTG（アイス・ガム・チョコ・ビス・キャン） | V32: — | W32: — | X32: — | Y32: — | Z32: 振返アイス, 振返ガム, 振返キャン, 振返チョコ, 振返ビス | AA32: — | AI32: e
A33: =ROW()-2 -> 31 | J33: 01_指標 | K33: =_xlfn.XLOOKUP(L33,'99_マスタ'!$D$5:$D$18,'99_マスタ'!$C$5:$C$18,"") -> 02_生販在 | L33: 07_販売 | M33: SCM見込み | N33: SCM見込 | O33: SCM需給部が独自に立案する販売見込み。生販会議資料・振り返りミーティングで営業見込みと並べて比較される。生産計画の基礎となる。 | Q33: 円, CS | R33: — | S33: — | T33: — | U33: 生販会議（販売振り返り・次月見込）、各カテゴリ振り返りMTG, SCM本部会議（販売見込み・前回生販会議振り返り） | V33: — | W33: — | X33: — | Y33: — | Z33: 生販会議, 振返アイス, 振返ガム, 振返キャン, 振返チョコ, 振返ビス, SCM本部会議全体, SCM会議 | AA33: — | AI33: e
A34: =ROW()-2 -> 32 | J34: 01_指標 | K34: =_xlfn.XLOOKUP(L34,'99_マスタ'!$D$5:$D$18,'99_マスタ'!$C$5:$C$18,"") -> 02_生販在 | L34: 07_販売 | M34: 規定値差 | N34: — | O34: 商品ごとに設定された値差補填の上限。これを超える条件提示には申請が必要。 | P34: Salesforce発売計画書で確認 | Q34: 円 | R34: Salesforce, 発売計画書 | S34: — | T34: — | U34: — | V34: — | W34: 菓初 | X34: — | Y34: — | Z34: — | AA34: — | AI34: e
A35: =ROW()-2 -> 33 | J35: 01_指標 | K35: =_xlfn.XLOOKUP(L35,'99_マスタ'!$D$5:$D$18,'99_マスタ'!$C$5:$C$18,"") -> 02_生販在 | L35: 07_販売 | M35: アイス定番値差 | N35: 定番補填 | O35: アイス特有の定番納価補填。新仕切制度（2021年）以前は仕切60掛けへの5%補填、現在は仕切に対し9.46%が標準。 | P35: 仕切 × 9.46%（現行180円商品で約8.892円） | Q35: 円 | R35: アイス見積書 | S35: — | T35: — | U35: — | V35: — | W35: 氷初 | X35: — | Y35: — | Z35: — | AA35: — | AI35: e
A36: =ROW()-2 -> 34 | J36: 01_指標 | K36: =_xlfn.XLOOKUP(L36,'99_マスタ'!$D$5:$D$18,'99_マスタ'!$C$5:$C$18,"") -> 01_財務・業績指標 | L36: 02_原価 | M36: コストダウン金額 | N36: CD金額 | O36: 原材料・包材・製造コスト等の削減額。生産本部（工場・資材部）のKPIとして管理される。 | Q36: 円 | R36: — | S36: — | T36: 目標管理実績（生産本部KPI） | U36: — | V36: 本部KPI | W36: — | X36: — | Y36: 目標管理実績 | Z36: — | AA36: 本部KPI確認 | AI36: e
A37: =ROW()-2 -> 35 | J37: 01_指標 | K37: =_xlfn.XLOOKUP(L37,'99_マスタ'!$D$5:$D$18,'99_マスタ'!$C$5:$C$18,"") -> 01_財務・業績指標 | L37: 02_原価 | M37: 洗浄ロス率 | N37: — | O37: 設備や貴部に付着した洗い流されてしまう原料や半製品の発生率 | P37: （洗浄ロス量×洗浄回数）/実績使用量×100 | Q37: ％ | R37: — | S37: — | T37: 原材料ロス管理 | U37: — | V37: — | W37: — | X37: — | Y37: 管理指標定義 | Z37: — | AA37: — | AI37: e
A38: =ROW()-2 -> 36 | J38: 01_指標 | K38: =_xlfn.XLOOKUP(L38,'99_マスタ'!$D$5:$D$18,'99_マスタ'!$C$5:$C$18,"") -> 01_財務・業績指標 | L38: 02_原価 | M38: 一次輸送費 | N38: 一次配送費 | O38: 工場（または物流センター）から物流センター（または直接大型卸の拠点）への輸送を指し、物流費の内訳の一つ。長距離・大量輸送が主体で、消費地に先に運ぶ政策（前送り政策）の影響を受けやすい。 | Q38: 円 | R38: — | S38: — | T38: — | U38: 月次物流費報告（一次輸送費の実績・予算・前年比管理）, SCM本部会議（SCM費項目別確認）, 物流費報告（物流企画一課） | V38: — | W38: — | X38: — | Y38: — | Z38: 物流費報告, SCM本部会議全体, 物流企画一課, 物流企画二課, SCM会議 | AA38: — | AI38: e
A39: =ROW()-2 -> 37 | J39: 01_指標 | K39: =_xlfn.XLOOKUP(L39,'99_マスタ'!$D$5:$D$18,'99_マスタ'!$C$5:$C$18,"") -> 01_財務・業績指標 | L39: 02_原価 | M39: 運賃・保管料 | N39: SCM費、物流費 | O39: SCMが管轄する一次輸送費、二次配送費、保管・荷役料にその他物流費を加算したKPI | P39: 一次輸送費＋二次配送費＋保管・荷役料＋その他物流費 | Q39: 円 | R39: — | S39: — | T39: — | U39: SCM会議（年度KPI） | V39: — | W39: — | X39: — | Y39: — | Z39: SCM会議 | AA39: — | AI39: e
A40: =ROW()-2 -> 38 | J40: 01_指標 | K40: =_xlfn.XLOOKUP(L40,'99_マスタ'!$D$5:$D$18,'99_マスタ'!$C$5:$C$18,"") -> 01_財務・業績指標 | L40: 02_原価 | M40: 運賃保管料率 | N40: 物流費率 | O40: 売上（総売高）に対する運賃・保管料の比率。物流コスト効率の管理KPI。 | P40: （運賃 + 保管料） ÷ 総売上高 × 100 | Q40: % | R40: 全国営業会議（物流費効率化KPI） | S40: — | T40: — | U40: SCM本部会議（物流費率管理） | V40: 収益性分析、KK定例会長報告、収益企画社長報告 | W40: 営政, 全営 | X40: — | Y40: — | Z40: SCM本部会議全体 | AA40: 2月個別決算、KK定例会長報告, 収益企画社長報告 | AI40: e
...

Sheet 99_マスタ
B2: プルダウン用マスタ
B4: 指標大分類 | C4: 指標タイプ | D4: 概念
B5: 01_指標 | C5: 01_財務・業績指標 | D5: 01_売上
B6: 02_マスタ | C6: 01_財務・業績指標 | D6: 02_原価
B7: 03_その他 | C7: 01_財務・業績指標 | D7: 03_販管費
C8: 01_財務・業績指標 | D8: 04_利益・損失
C9: 01_財務・業績指標 | D9: 05_資産・負債
C10: 02_生販在 | D10: 06_生産
C11: 02_生販在 | D11: 07_販売
C12: 02_生販在 | D12: 08_SCM
C13: 02_生販在 | D13: 09_商品名・ブランド
C14: 03_会社運営 | D14: 10_システム
C15: 03_会社運営 | D15: 11_組織
C16: 03_会社運営 | D16: 12_人材
C17: 03_会社運営 | D17: 13_業務・プロジェクト
C18: 03_会社運営 | D18: 14_その他
